Workbook

Sheet 总表
J2: 人物属性
C3: 基础属性 | D3: 血量 | E3: 攻击 | F3: 物理防御 | G3: 魔法防御 | K3: 属性占比 | L3: 血量占比 | M3: 血量最大值 | N3: 攻击最大值 | O3: 防御最大值 | R3: 宠物属性 | S3: 属性占比 | T3: 血量占比 | U3: 攻击 | V3: 血量 | W3: 防御
D4: =(E4-F4)*D7 -> 1050 | E4: 100 | F4: 30 | G4: 30 | J4: 基础属性 | K4: 5 | L4: 5 | M4: =L4*$D$4 -> 5250 | N4: =K4*$E$4 -> 500 | O4: =G4*K4 -> 150 | R4: 基础比例 | S4: 1 | T4: 1 | U4: 500 | V4: 5000 | W4: 200
J5: 升级属性 | K5: 10 | L5: 20 | M5: =L5*$D$4 -> 21000 | N5: =K5*$E$4 -> 1000 | O5: =G4*K5 -> 300 | R5: 基础属性 | S5: 2.5 | T5: 2.5 | U5: =U4*S5 -> 1250 | V5: =V4*T5 -> 12500 | W5: =W4*S5 -> 500
E6: 普通 | F6: 技能 | J6: 装备属性 | K6: 35 | L6: 25 | M6: =L6*$D$4 -> 26250 | N6: =K6*$E$4 -> 3500 | O6: =$G$4*K6 -> 1050 | R6: 成长属性 | S6: 7 | T6: 7 | U6: =S6*U4 -> 3500 | V6: =T6*V4 -> 35000 | W6: =S6*W4 -> 1400
C7: 期待回合数 | D7: 15 | E7: 7.5 | F7: 7.5 | J7: 宝石属性 | K7: 10 | L7: 10 | M7: =L7*$D$4 -> 10500 | N7: =K7*$E$4 -> 1000 | O7: =$G$4*K7 -> 300
U8: =U6+U5 -> 4750 | V8: =V6+V5 -> 47500 | W8: =W6+W5 -> 1900
P9: 验证回合数
J10: 总属性 | K10: =SUM(K$4:K$7) -> 60 | L10: =SUM(L$4:L$7) -> 60 | M10: =SUM(M$4:M$7) -> 63000 | N10: =SUM(N$4:N$7) -> 6000 | O10: =SUM(O$4:O$7) -> 1800 | P10: =M10/(N10-O10) -> 15
J14: 宠物属性
K15: 属性占比 | L15: 血量占比 | M15: 血量最大值 | N15: 攻击最大值 | O15: 防御最大值
J16: 基础属性 | K16: 20 | L16: 10 | M16: =L16*$D$4 -> 10500 | N16: =K16*$E$4 -> 2000 | O16: =L16*$F$4 -> 300
J17: 加点属性 | K17: 10 | L17: 10 | M17: =L17*$D$4 -> 10500 | N17: =K17*$E$4 -> 1000 | O17: =L17*$F$4 -> 300
J18: 宠物之核 | K18: 15 | L18: 15 | M18: =L18*$D$4 -> 15750 | N18: =K18*$E$4 -> 1500 | O18: =L18*$F$4 -> 450
J21: 总属性 | K21: =SUM(K$4:K$7) -> 60 | L21: =SUM(L$4:L$7) -> 60 | M21: =SUM(M$4:M$7) -> 63000 | N21: =SUM(N$4:N$7) -> 6000 | O21: =SUM(O$4:O$7) -> 1800

Sheet 属性介绍
J1: 表现效果参考
B2: 属性 | D2: 效果 | G2: 技能属性类型 | H2: 火系 | I2: 灼烧：持续受到伤害；叠满后触发爆燃
B3: 生命值 | C3: 固定值 | D3: 角色能够承受的伤害 | H3: 水系 | I3: 潮湿：降低移动速度，并强化电系效果
B4: 攻击力 | C4: 固定值 | D4: 提高普通攻击和技能基础伤害 | H4: 电系 | I4: 感电：受到攻击时有概率将此伤害向附近敌人传导伤害 | J4: 传到一个人有电击的效果,逐个的传递
B5: 防御力 | C5: 固定值 | D5: 减少受到的物理伤害 | H5: 暗系 | I5: 侵蚀：降低防御和受到的治疗效果
B6: 法术强度 | C6: 固定值 | D6: 提高魔法技能的伤害效果 | H6: 光系 | I6: 圣痕：目标受到的伤害提高
B7: 攻击强度 | C7: 固定值 | D7: 提高近战普通攻击的效果 | H7: 自然 | I7: 中毒：持续伤害,并降低移动速度
B8: 攻击速度 | C8: 百分比 | D8: 提高普通攻击频率
B9: 移动速度 | C9: 固定值 | D9: 提高角色移动速度
B10: 暴击率 | C10: 百分比 | D10: 攻击产生暴击的概率 | K10: 对比属性 | L10: 如果当前属性比玩家属性高
B11: 抗暴率 | C11: 百分比 | D11: 抵抗暴击的概率 | G11: 一类属性 | H11: 力量 | I11: 增加攻击属性 | J11: 增加普攻伤害 | K11: 力量 | L11: 命中提升5%
B12: 命中率 | C12: 百分比 | D12: 降低攻击落空概率 | H12: 智力 | I12: 提高法术强度 | J12: 增加所有技能类伤害 | K12: 智力 | L12: 技能伤害提升5%
B13: 闪避率 | C13: 百分比 | D13: 有概率完全躲避攻击 | H13: 敏捷 | I13: 提高攻击强度 | J13: 伤害加成 | K13: 敏捷 | L13: 暴击提升5%
B14: 冷却缩减 | C14: 百分比 | D14: 减少技能冷却时间 | H14: 体质 | I14: 提高生命值 | J14: 伤害减免 | K14: 体质 | L14: 抗暴提升5%
B15: 破甲 | C15: 百分比 | D15: 降低敌人防御力 | H15: 耐力 | I15: 提高防御属性 | J15: 增加自身的技能抵抗概率和格挡的概率 | K15: 耐力 | L15: 闪避提升5%
B16: 穿透 | C16: 百分比 | D16: 每次攻击概率忽略目标的抗性或护甲
B17: 斩击 | C17: 百分比 | D17: 当目标血量低于30%,额外造成的伤害
B18: 溅射 | C18: 百分比 | D18: 对有主目标的普通攻击和技能攻击的伤害可以扩散到附近的单位 | H18: =4*4*4 -> 64
B19: 格挡 | C19: 百分比 | D19: 有一定概率抵抗普通攻击造成的伤害
B20: 技能抵抗 | C20: 百分比 | D20: 受到技能将会减免一定的伤害
B21: 伤害加成 | C21: 百分比 | D21: 造成伤害的总加成
B22: 伤害减免 | C22: 百分比 | D22: 受到伤害的总减免
B23: 首领增伤 | C23: 百分比 | D23: 增加Boss造成的伤害
B24: 首领减伤 | C24: 百分比 | D24: 减少Boss造成的伤害
B25: 治疗增效 | C25: 百分比 | D25: 恢复药剂的生命以及恢复类技能的恢复量提高
B26: 免费施法 | C26: 百分比 | D26: 技能有概率不进入冷却时间
B27: 金币加成 | C27: 百分比 | D27: 提高获得的金币
B28: 经验加成 | C28: 百分比 | D28: 提高获得的经验
B29: 暴击伤害 | C29: 百分比 | D29: 暴击时造成的额外伤害
B30: 异常抗性 | C30: 百分比 | D30: 降低负面状态命中概率
B31: 反弹伤害 | C31: 百分比 | D31: 受到伤害有一定概率将此伤害反弹给目标敌人
B33: 火系伤害 | C33: 百分比 | D33: 每个技能有对应的系列,对应系列的技能伤害提升 | F33: 可以
B34: 水系伤害 | C34: 百分比 | D34: 每个技能有对应的系列,对应系列的技能伤害提升
B35: 电系伤害 | C35: 百分比 | D35: 每个技能有对应的系列,对应系列的技能伤害提升
B36: 暗系伤害 | C36: 百分比 | D36: 每个技能有对应的系列,对应系列的技能伤害提升
B37: 光系伤害 | C37: 百分比 | D37: 每个技能有对应的系列,对应系列的技能伤害提升
B38: 自然伤害 | C38: 百分比 | D38: 每个技能有对应的系列,对应系列的技能伤害提升
B39: 火系抗性 | C39: 百分比 | D39: 每个技能有对应的系列,对应系列的技能抗性提升
B40: 水系抗性 | C40: 百分比 | D40: 每个技能有对应的系列,对应系列的技能抗性提升
B41: 电系抗性 | C41: 百分比 | D41: 每个技能有对应的系列,对应系列的技能抗性提升
...

Sheet 等级属性
A1: 等级 | B1: 血量系数 | C1: 属性系数 | D1: 血量 | E1: 攻击 | F1: 物防 | G1: 魔防
A2: 1 | B2: 5 | C2: 5 | D2: =B2*[1]属性总表!$E$5 -> 5250 | E2: =ROUND([1]等级属性!C2*[1]属性总表!$F$5,0) -> 500 | F2: =ROUND(C2*[1]属性总表!$G$5,0) -> 150 | G2: =ROUND(C2*[1]属性总表!$H$5,0) -> 150
A3: 2 | B3: =B2+0.25 -> 5.25 | C3: =C2+0.12 -> 5.12 | D3: =B3*[1]属性总表!$E$5 -> 5512.5 | E3: =ROUND([1]等级属性!C3*[1]属性总表!$F$5,0) -> 512 | F3: =ROUND(C3*[1]属性总表!$G$5,0) -> 154 | G3: =ROUND(C3*[1]属性总表!$H$5,0) -> 154 | H3: =D3-D2 -> 262.5
A4: 3 | B4: =B3+0.25 -> 5.5 | C4: =C3+0.12 -> 5.24 | D4: =B4*[1]属性总表!$E$5 -> 5775 | E4: =ROUND([1]等级属性!C4*[1]属性总表!$F$5,0) -> 524 | F4: =ROUND(C4*[1]属性总表!$G$5,0) -> 157 | G4: =ROUND(C4*[1]属性总表!$H$5,0) -> 157
A5: 4 | B5: =B4+0.25 -> 5.75 | C5: =C4+0.12 -> 5.36 | D5: =B5*[1]属性总表!$E$5 -> 6037.5 | E5: =ROUND([1]等级属性!C5*[1]属性总表!$F$5,0) -> 536 | F5: =ROUND(C5*[1]属性总表!$G$5,0) -> 161 | G5: =ROUND(C5*[1]属性总表!$H$5,0) -> 161
A6: 5 | B6: =B5+0.25 -> 6 | C6: =C5+0.12 -> 5.48 | D6: =B6*[1]属性总表!$E$5 -> 6300 | E6: =ROUND([1]等级属性!C6*[1]属性总表!$F$5,0) -> 548 | F6: =ROUND(C6*[1]属性总表!$G$5,0) -> 164 | G6: =ROUND(C6*[1]属性总表!$H$5,0) -> 164
A7: 6 | B7: =B6+0.25 -> 6.25 | C7: =C6+0.12 -> 5.6 | D7: =B7*[1]属性总表!$E$5 -> 6562.5 | E7: =ROUND([1]等级属性!C7*[1]属性总表!$F$5,0) -> 560 | F7: =ROUND(C7*[1]属性总表!$G$5,0) -> 168 | G7: =ROUND(C7*[1]属性总表!$H$5,0) -> 168
A8: 7 | B8: =B7+0.25 -> 6.5 | C8: =C7+0.12 -> 5.72 | D8: =B8*[1]属性总表!$E$5 -> 6825 | E8: =ROUND([1]等级属性!C8*[1]属性总表!$F$5,0) -> 572 | F8: =ROUND(C8*[1]属性总表!$G$5,0) -> 172 | G8: =ROUND(C8*[1]属性总表!$H$5,0) -> 172
A9: 8 | B9: =B8+0.25 -> 6.75 | C9: =C8+0.12 -> 5.84 | D9: =B9*[1]属性总表!$E$5 -> 7087.5 | E9: =ROUND([1]等级属性!C9*[1]属性总表!$F$5,0) -> 584 | F9: =ROUND(C9*[1]属性总表!$G$5,0) -> 175 | G9: =ROUND(C9*[1]属性总表!$H$5,0) -> 175
A10: 9 | B10: =B9+0.25 -> 7 | C10: =C9+0.12 -> 5.96 | D10: =B10*[1]属性总表!$E$5 -> 7350 | E10: =ROUND([1]等级属性!C10*[1]属性总表!$F$5,0) -> 596 | F10: =ROUND(C10*[1]属性总表!$G$5,0) -> 179 | G10: =ROUND(C10*[1]属性总表!$H$5,0) -> 179
A11: 10 | B11: =B10+0.25 -> 7.25 | C11: =C10+0.12 -> 6.08 | D11: =B11*[1]属性总表!$E$5 -> 7612.5 | E11: =ROUND([1]等级属性!C11*[1]属性总表!$F$5,0) -> 608 | F11: =ROUND(C11*[1]属性总表!$G$5,0) -> 182 | G11: =ROUND(C11*[1]属性总表!$H$5,0) -> 182
A12: 11 | B12: =B11+0.25 -> 7.5 | C12: =C11+0.12 -> 6.2 | D12: =B12*[1]属性总表!$E$5 -> 7875 | E12: =ROUND([1]等级属性!C12*[1]属性总表!$F$5,0) -> 620 | F12: =ROUND(C12*[1]属性总表!$G$5,0) -> 186 | G12: =ROUND(C12*[1]属性总表!$H$5,0) -> 186
A13: 12 | B13: =B12+0.25 -> 7.75 | C13: =C12+0.12 -> 6.32 | D13: =B13*[1]属性总表!$E$5 -> 8137.5 | E13: =ROUND([1]等级属性!C13*[1]属性总表!$F$5,0) -> 632 | F13: =ROUND(C13*[1]属性总表!$G$5,0) -> 190 | G13: =ROUND(C13*[1]属性总表!$H$5,0) -> 190
A14: 13 | B14: =B13+0.25 -> 8 | C14: =C13+0.12 -> 6.44 | D14: =B14*[1]属性总表!$E$5 -> 8400 | E14: =ROUND([1]等级属性!C14*[1]属性总表!$F$5,0) -> 644 | F14: =ROUND(C14*[1]属性总表!$G$5,0) -> 193 | G14: =ROUND(C14*[1]属性总表!$H$5,0) -> 193
A15: 14 | B15: =B14+0.25 -> 8.25 | C15: =C14+0.12 -> 6.56 | D15: =B15*[1]属性总表!$E$5 -> 8662.5 | E15: =ROUND([1]等级属性!C15*[1]属性总表!$F$5,0) -> 656 | F15: =ROUND(C15*[1]属性总表!$G$5,0) -> 197 | G15: =ROUND(C15*[1]属性总表!$H$5,0) -> 197
... A71: 70 | B71: =B70+0.25 -> 22.25 | C71: =C70+0.12 -> 13.28 | D71: =B71*[1]属性总表!$E$5 -> 23362.5 | E71: =ROUND([1]等级属性!C71*[1]属性总表!$F$5,0) -> 1328 | F71: =ROUND(C71*[1]属性总表!$G$5,0) -> 398 | G71: =ROUND(C71*[1]属性总表!$H$5,0) -> 398

Sheet 活力属性
B2: 制造品质 | F2: 最高熟练度500 | K2: 等级 | L2: 熟练度上线
F3: 制造1个提升1-3点 | K3: 20 | L3: 200 | N3: 150 | P3: =N3/L3*50 -> 37.5 | Q3: =N3/L3*100 -> 75
K4: 30 | L4: 300
I5: =500/3 -> 166.66667 | K5: 40 | L5: 400
K6: 50 | L6: 500

Sheet 技能
AC1: 魔杖 | AD1: 单体攻击
S2: 元素武士 | AC2: 魔法书 | AD2: 群体攻击 | AR2: 增加一个法师分身 | BL2: 怒气每秒10点怒气,上限是100点 | BY2: 游侠 | CA2: 武器 | CB2: 弓箭 | CC2: 剑
B3: 战士 | C3: 武器 | D3: 等级 | E3: 需要怒气 | F3: 技能名称 | G3: 技能效果 | I3: 10001 | J3: 专精系统 | K3: 18级 | L3: 天赋1 | M3: 生命恢复 | N3: 新增技能生命回复,可以立即回复自身20%生命,15秒冷却时间 | R3: 转职专精 | S3: 1 | T3: 速度专精：移动速度提升10% | V3: =T3&","&T4&","&T5 -> 速度专精：移动速度提升10%,装备精通：布甲,移动光环：小队内移动速度提升10% | AB3: 法师 | AC3: 武器 | AD3: 等级 | AE3: 需要怒气 | AF3: 技能名称 | AG3: 技能效果 | AN3: 职业技能 | BK3: 战士 | BL3: 武器 | BM3: 等级 | BN3: 需要怒气 | BO3: 技能名称 | BP3: 技能效果
C4: 刀 | D4: 1 | F4: 裂地斩 | G4: 对前方区域造成200%伤害。 | I4: 10002 | L4: 天赋2 | M4: 强击 | N4: 新增强击技能,立即对目标造成200%伤害 | S4: 2 | T4: 装备精通：布甲 | Z4: 22000010 | AA4: 22000010 | AC4: 魔杖 | AD4: 1 | AF4: 魔法闪击 | AG4: 对指定区域造成200%伤害 | AN4: 魔导师 | AO4: 不限 | AP4: 20 | AR4: 瞬移闪击 | AS4: 瞬间前往目标区域并在原地造成150%伤害,眩晕1秒 | AV4: 10001 | AW4: 专精系统 | AX4: 18级 | AY4: 天赋1 | AZ4: 伤害增幅 | BA4: 魔法闪击和龙卷雨击伤害提升50% | BI4: Eff_Skill_BaoZha_23(Clone) | BK4: Bullet_BlazingRed_Big_Projectile | BL4: 弓箭 | BM4: 1 | BN4: 30 | BO4: 震荡射击 | BP4: 对前方区域射出一直强有力的震荡箭,造成200%伤害,并使其减速50% | CA4: 射击 | CC4: 兽王
C5: 剑 | D5: 1 | F5: 裂地击 | G5: 对前方区域造成150%伤害,并让目标防御降低50%,持续6秒 | I5: 10003 | L5: 天赋3 | M5: 伤害上升 | N5: 裂地击和裂波击伤害提升50% | S5: 3 | T5: 移动光环：小队内移动速度提升10% | Z5: 22000020 | AA5: E3D-Spell-Wind-Blue2(Clone) | AC5: 魔法书 | AD5: 1 | AF5: 龙卷雨击 | AG5: 对指定区域造成150%伤害,并降低目标移动速度50%,持续3秒 | AM5: E3D-Skill-Blast-Orange1 | AN5: E3D-Spell-Wind-Orange2 | AP5: 25 | AR5: 冲击波 | AS5: 向前方发射一个可移动的光球,触碰的单位造成200%伤害 | AV5: 10002 | AY5: 天赋2 | AZ5: 轰击 | BA5: 新增技能:轰击 立即对目标及其范围造成200%伤害 | BI5: Daofeng_Atk_Q_DeBuff(Clone) | BK5: Eff_Skill_FireWall_13 | BL5: 剑 | BM5: 1 | BN5: 30 | BO5: 奥义投掷 | BP5: 像前方发射一个魔球,魔球在向前方飞行10秒会原路径返回,对触碰的单位造成150%伤害。 | BY5: 审判者 | CA5: 猎影 | CC5: 驯兽师
I6: 10011 | K6: 22级 | L6: 天赋1 | M6: 技能刷新 | N6: 每次攻击暴击后5%的概率自动触发裂地斩技能,且不影响主技能的冷却时间 | AL6: E3D-Skill-Direct-Front-Blue1(Clone) | AN6: E3D-Ballistic-Continuous-Violet1(Clone) | AP6: 30 | AR6: 熔岩大地 | AS6: 对目标区域释放火焰灼烧,每秒造成100%伤害,持续6秒 | AV6: 10003 | AY6: 天赋3 | AZ6: 减速之术 | BA6: 普通攻击附带20%减速效果,持续3秒 | BY6: 隐身
C7: 刀 | D7: 7 | F7: 回旋击 | G7: 对目标前方目标区域造成150%伤害，并造成1秒眩晕效果 | I7: 10012 | L7: 天赋2 | M7: 进退自由 | N7: 跳跃斩和冲锋斩会对目标区域内造成3秒眩晕的效果 | Z7: 22000030 | AA7: E3D-Skill-Blast-Violet1 | AC7: 魔杖 | AD7: 7 | AF7: 禁锢之术 | AG7: 对目标前方目标区域造成150%伤害，并造成1秒眩晕效果 | AM7: E3D-Skill-Blast-Orange | AN7: E3D-Spell-Vertical-Orange2(Clone) | AP7: 35 | AR7: 魔导之身 | AS7: 召唤一个自己的分身协助自身攻击 | AV7: 10011 | AX7: 22级 | AY7: 天赋1 | AZ7: 龙卷增强 | BA7: 攻击有5%概率对目标释放龙卷雨击 | BJ7: Weien_Atk_W_Buff(Clone) | BL7: 弓箭 | BM7: 7 | BN7: 50 | BO7: 召唤野兽 | BP7: 可以召唤一只野兽协助自己攻击(还是说直接捕捉野外的怪物)
C8: 剑 | D8: 7 | F8: 旋风斩 | G8: 持续性的旋转每秒造成60%伤害，持续5秒，旋转时可自由移动 | I8: 10013 | L8: 天赋3 | M8: 圣光之速 | N8: 圣光之速,提升自身移动速度200%,持续6秒 | Z8: 22000040 | AA8: Eff_Skill_ChiXu_7 | AC8: 魔法书 | AD8: 7 | AF8: 烈焰灼烧 | AG8: 对目标区域释放火焰灼烧,每秒造成50%伤害,持续6秒 | AP8: 被动 | AR8: 职业专属被动 | AS8: 攻击有3%概率释放冲击波技能 | AV8: 10012 | AY8: 天赋2 | AZ8: 冰冻击 | BA8: 新增技能:冰冻击 立即对前方矩形范围的目标造成200%伤害,并使其眩晕1秒 | BL8: 剑 | BM8: 7 | BN8: 30 | BO8: 奥义之击 | BP8: 对于前方单体目标造成200%伤害，如目标生命低于30%的则造成伤害提升50% | BY8: 跟召唤兽合体 | CN8: 10001 | CO8: 专精系统 | CP8: 18级 | CQ8: 天赋1 | CR8: 生命恢复 | CS8: 每次攻击概率恢复己方一定生命值
I9: 10021 | K9: 27级 | L9: 天赋1 | M9: 暴击上升 | N9: 暴击概率永久提升5% | S9: 光之剑魂 | AR9: 职业光环 | AS9: 附近己方单位防御效果增加10% | AV9: 10013 | AY9: 天赋3 | AZ9: 伤害增加 | BA9: 守护之击和冰锥之击使目标受到伤害增加50%,持续6秒 | BZ9: 1技能寒冰箭:向前方发射一枚巨大的寒冰箭矢，命中敌人造成50%减速并冰冻敌方一秒。 | CI9: Eff_Skill_ChiXu_19 | CN9: 10002 | CQ9: 天赋2 | CR9: 凶猛 | CS9: 立即提升己方和召唤兽的100%攻击速度,持续6秒
C10: 刀 | D10: 12 | F10: 跳跃斩 | G10: 跳跃至指定区域，对目标区域造成150%伤害 | I10: 10022 | L10: 天赋2 | M10: 职业专精 | N10: 职业专属被动技能效果提升至5% | S10: 1 | T10: 刀类专精：使用剑类武器伤害提升5% | V10: =T10&","&T11&","&T12 -> 刀类专精：使用剑类武器伤害提升5%,装备精通：轻甲,暴击光环：小队内暴击概率提升5% | Z10: 22000050 | AA10: E3D-Buff-Continuous-Orange2(Clone) | AC10: 魔杖 | AD10: 12 | AF10: 守护之击 | AG10: 对己方周围区域造成150%伤害,并将其向后击退 | AM10: 控制 | AV10: 10021 | AX10: 27级 | AY10: 天赋1 | AZ10: 英勇守护 | BA10: 受到伤害有5%概率触发守护之击 | CN10: 10003 | CQ10: 天赋3 | CR10: 伤害上升 | CS10: 震荡射击的伤害提升50%
C11: 剑 | D11: 12 | F11: 冲锋斩 | G11: 冲锋至前方区域，对目标区域造成150%伤害 | I11: 10023 | L11: 天赋3 | M11: 技能专精 | N11: 元素护盾: 护盾效果提升50% 光能斩:伤害提升50% 能量吸附:伤害提升50% | S11: 2 | T11: 装备精通：轻甲 | Z11: 22000060 | AA11: E3D-Damage-Sword-Orange1 | AC11: 魔法书 | AD11: 12 | AF11: 冰锥之击 | AG11: 蓄力1秒,对前方区域造成300%伤害 | AM11: E3D-Skill-Front-Orange2(Clone) | AN11: 光灵使者 | AP11: 20 | AR11: 精灵之击 | AS11: 对当前目标造成300%伤害,并使其眩晕2秒 | AV11: 10022 | AY11: 天赋2 | AZ11: 技能专精 | BA11: 魔法护盾: 护盾效果提升50% 精灵之击:伤害提升50% 治愈之术:伤害提升50% | BK11: Eff_Skill_GongJian_Skill_1/Eff_Skill_GongJian_Skill_1_Hit | BL11: 弓箭 | BM11: 12 | BN11: 35 | BO11: 散射 | BP11: 射出扇形的散箭攻击目标造成200%伤害,并使攻击目标造成1秒眩晕 | BW11: 布甲 | BY11: 生存 | CN11: 10011 | CP11: 22级 | CQ11: 天赋1 | CR11: 爆炸种子 | CS11: 每次攻击会在目标种下一颗爆炸种子,3秒后发生爆炸对范围内的敌人造成250%伤害
I12: 10031 | K12: 32级 | L12: 天赋1 | M12: 防御之盾 | N12: 每20秒自动自身释放一个护盾,护盾可以抵抗50%伤害,持续20秒 | S12: 3 | T12: 暴击光环：小队内暴击概率提升5% | AN12: E3D-Relive-Light-Green | AP12: 25 | AR12: 暴焰燃烧 | AS12: 持续引导释放,对目标区域持续造成100%伤害,持续6秒，对造成伤害的目标移动速度降低50%,持续3秒 | AV12: 10023 | AY12: 天赋3 | AZ12: 意念之勇 | BA12: 攻击有5%概率使自身获得10%伤害加成,持续10秒 | BI12: E3D-Ballistic-Blast-Green1(Clone)(自身跳一下) | BK12: 46_RFX_Straight_IceWall1 | BL12: 剑 | BM12: 12 | BN12: 35 | BO12: 奥义守护 | BP12: 向后跳跃并向前方，对前方范围造成200%伤害,并使移动速度和命中降低30%,持续6秒 | BW12: Eff_Skill_BaoZha_23+Eff_Skill_BaoZha_21 | BX12: 30 | BY12: 冰冻陷阱 | BZ12: 释放一个冰冻陷阱,3秒后陷阱进入准备状态,对触碰的单位造成伤害和减速效果 | CG12: Eff_Skill_BaoZha_44 | CN12: 10012 | CQ12: 天赋2 | CR12: 野兽强壮 | CS12: 召唤的野兽攻击和血量提升20%
B13: 职业技能 | I13: 10032 | L13: 天赋2 | M13: 猛击 | N13: 新增技能：猛击 立即对目标造成300%伤害,如果目标血量低于30%,伤害提升50% | AM13: E3D-Buff-Absorb-Red | AN13: E3D-Skill-Blast-Orange1 | AP13: 30 | AR13: 点燃 | AS13: 给目标释放点燃,点燃目标每2秒会在自己脚下生成1个灼烧，灼烧会对附近的己方单位造成100%伤害 | AV13: 10031 | AX13: 32级 | AY13: 天赋1 | AZ13: 攻击提升 | BA13: 攻击永久提升5% | BP13: 上面这个技能在天赋里附加一个,释放技能自身可以向后跳跃 | BU13: E3D-Ground-Skill-Boom(Clone) E3D-Skill-Blast-Orange1(Clone) | BW13: Mon_Zhadankongzei_Atk_Q(Clone) | BX13: 35 | BY13: 爆炸陷阱 | BZ13: 释放一个爆炸陷阱,3秒后陷阱进入准备状态，目标将造成伤害和眩晕效果 | CG13: Eff_Skill_BaoZha_45 | CN13: 10013 | CQ13: 天赋3 | CR13: 散射眩晕 | CS13: 散射的技能伤害提升50%
B14: 逐风者 | C14: 不限 | D14: 20 | F14: 元素护盾 | G14: 对自身释放一个护盾,护盾可以抵抗自身最大生命100%的伤害,持续30秒 | I14: 10033 | L14: 天赋3 | M14: 技能升阶 | N14: 元素光球:对触碰到的玩家移动速度降低50% 光剑攻击:持续时间延长至10秒 狂魔状态:伤害提升至60% | AB14: 伤害 | AC14: 光之魔导 | AN14: E3D-Ground-Blast-Violet1(Clone) | AP14: 35 | AR14: 精灵轰击 | AS14: 吟唱2秒, 对目标区域造成300%伤害,并眩晕1秒 | AV14: 10032 | AY14: 天赋2 | AZ14: 技能专精 | BA14: 瞬移闪击: 眩晕效果延长至2秒 爆焰燃烧:效果延长时间增加4秒 治愈之境:恢复效果由1%提升至2% | BL14: 近战/远程姿态切换 | BU14: Mon_Bingjuren_Atk_W(Clone) | BW14: Common_XJ_bingci(Clone) | BX14: 40 | BY14: 冰封之地 | BZ14: 在一个大范围内,敌方目标持续降低移动速度和受到伤害 | CG14: Eff_Skill_ChiXu_14 | CN14: 10021 | CP14: 27级 | CQ14: 天赋1 | CR14: 重击之力 | CS14: 重击概率永久提升5%
D15: 25 | F15: 元素光球 | G15: 向前方发射一颗移动缓慢的球体,球体每秒对附近玩家造成120%伤害,持续6秒,并降低目标移动速度50% | I15: 10041 | K15: 37级 | L15: 天赋1 | M15: 攻击恢复 | N15: 普通攻击有3%概率回复自身最大生命的1% | AB15: 控制 | AC15: 精灵魔师 | AP15: 被动 | AR15: 职业专属被动 | AS15: 暴击攻击有10%概率向目标触发精灵之击的技能 | AV15: 10033 | AY15: 天赋3 | AZ15: 坚韧 | BA15: 当生命值降低至30%后,受到伤害减免30% | BL15: 消耗能量切换姿态？ | BX15: 50 | BY15: 火舌守卫 | BZ15: 召唤一个毒蛇陷阱,每个毒蛇有自己的攻击,但是不能移动，只能在附近区域进行攻击 | CN15: 10022 | CQ15: 天赋2 | CR15: 冰寒之箭 | CS15: 每次攻击有概率降低目标30%移动速度,持续5秒
D16: 30 | F16: 元素爆冰 | G16: 对前方区域造成250%伤害,并造成3秒眩晕 | I16: 10042 | L16: 天赋2 | M16: 生命护盾 | N16: 当生命低于30%时,自动获得一个护盾,可以抵抗相当于自身100%生命的伤害,30秒冷却时间 | S16: 魔神战士 | AB16: 治疗 | AC16: 心灵之师 | AR16: 职业光环 | AS16: 附近敌方单位移动速度降低10% | AV16: 10041 | AX16: 37级 | AY16: 天赋1 | AZ16: 守护之击 | BA16: 新增技能:守护之击 立即对周围敌方目标造成200%伤害,并眩晕1秒 | CN16: 10023 | CQ16: 天赋3 | CR16: 技能专精 | CS16: 冰冻陷阱: 冷却时间降低2秒 灼热之箭:伤害提升50% 野兽爆发:爆发状态延长3秒
D17: 35 | F17: 元素爆裂 | G17: 对目标区域造成300%伤害，并使目标区域移动速度降低50%,持续3秒 | I17: 10043 | L17: 天赋3 | M17: 职业专精 | N17: 元素烈波: 触碰到的目标移动速度降低50%,持续6秒 光之能量:伤害范围增加,伤害提升至75% 狂魔之球:伤害提升至125% | S17: 1 | T17: 刀类专精：使用刀类武器伤害提升5% | V17: =T17&","&T18&","&T19 -> 刀类专精：使用刀类武器伤害提升5%,装备精通：重甲,伤害光环：小队内造成伤害提升5% | AV17: 10042 | AY17: 天赋2 | AZ17: 技能专精 | BA17: 冲击波: 对受到伤害的目标单位时期原地禁锢3秒,无法移动 灼烧轰击:效果延长时间增加4秒 心灵之击:伤害提升50% | BV17: E3D-Skill-Continuous-Orange-Loop(Clone) | BW17: 觉醒 | BZ17: 在一个范围持续性伤害 | CG17: Eff_Skill_ChiXu_15 | CN17: 10031 | CP17: 32级 | CQ17: 天赋1 | CR17: 暴击之力 | CS17: 普通攻击暴击时会让自身伤害提升20%,持续6秒
D18: 被动 | F18: 职业专属被动 | G18: 普通攻击有3%概率向目标发送元素裂波的技能 | I18: 10051 | K18: 42级 | L18: 天赋1 | M18: 最后希望 | N18: 在生命值低于5%时,立即回复自身20%最大生命,120秒冷却时间 | S18: 2 | T18: 装备精通：重甲 | AM18: E3D-Relive-Light-Green | AN18: 神圣牧师 | AP18: 20 | AR18: 魔法护盾 | AS18: 对自身释放一个护盾,护盾可以抵抗自身最大生命100%的伤害,持续10秒 | AV18: 10043 | AY18: 天赋3 | AZ18: 速度增幅 | BA18: 移动速度永久提升10% | BN18: 近战状态 | CN18: 10032 | CQ18: 天赋2 | CR18: 怒气 | CS18: 每次释放技能有一定概率恢复一定怒气值
F19: 职业光环 | G19: 附近友方玩家命中概率提升+5% | I19: 10052 | L19: 天赋2 | M19: 爆裂轰炸 | N19: 新增技能：爆裂轰炸 对自身范围内每秒持续造成100%伤害,持续6秒 | S19: 3 | T19: 伤害光环：小队内造成伤害提升5% | AM19: TX_DLD_chushengdian(Clone) | AO19: Eff_Skill_QunLiao_1 | AP19: 25 | AR19: 治愈之境 | AS19: 对目标区域释放治愈权杖,附近单位每秒恢复最大生命值1%的生命值,怪物每秒损失30%的生命值,持续10秒 | AV19: 10051 | AX19: 42级 | AY19: 天赋1 | AZ19: 暴击恢复 | BA19: 每次攻击暴击后,立即回复己方最大生命的3% | BN19: 能量饥渴 | BO19: 血量越少,攻击伤害越高 | BW19: 被动 | CN19: 10033 | CQ19: 天赋3 | CR19: 技能升阶 | CS19: 爆炸陷阱:造成暴击后会对目标附加1秒眩晕 眩晕射击:技能伤害提升50% 狩猎标记:伤害提升10%
I20: 10053 | L20: 天赋3 | M20: 职业升阶 | N20: 元素爆裂：技能的伤害范围增加增加,伤害提升至400%伤害 光之斩:技能伤害增加至400%,眩晕增加至3秒 狂魔之地:效果提升至50% | AB20: 召唤 | AC20: 召唤魔师 | AN20: E3D-Relive-Light-Green | AP20: 30 | AR20: 心灵之击 | AS20: 对目标范围造成200%伤害,并使其收到伤害增加50%,持续6秒 | AV20: 10052 | AY20: 天赋2 | AZ20: 技能专精 | BA20: 熔岩大地: 伤害提升25% 精灵轰击:眩晕效果延长至3秒 心灵治愈:治疗效果提升30% | BN20: 巨魔光环 | BO20: 周围掉血 | BY20: 职业光环 | BZ20: 物理穿透提升10% | CN20: 10041 | CP20: 37级 | CQ20: 天赋1 | CR20: 射击专精 | CS20: 每次使用弓箭攻击目标有概率造成200%伤害
B21: 驭剑士 | D21: 20 | F21: 光能斩 | G21: 超大范围攻击,对附近区域造成200%伤害 | I21: 10051 | K21: 52级 | L21: 天赋1 | M21: 闪避之击 | N21: 每次闪避目标攻击有概率对目标造成一次攻击伤害 | AN21: E3D-Spell-Cure-Green2 | AP21: 35 | AR21: 心灵治愈 | AS21: 对目标区域恢复相当于自身攻击100%的生命值,并对范围内己方玩家攻击提升25%,持续10秒 | AV21: 10053 | AY21: 天赋3 | AZ21: 移动光球 | BA21: 新增技能: 移动光球,对前方区域释放一个移动的光球,对触碰到的单位造成200%伤害 | BZ21: 每次攻击有概率触发震荡射击 | CN21: 10042 | CQ21: 天赋2 | CR21: 生命护盾 | CS21: 当生命低于30%时,自动获得一个护盾,可以抵抗相当于自身100%生命的伤害,30秒冷却时间
D22: 25 | F22: 光剑攻击 | G22: 立即给自己的武器附带光电效果,攻击目标将降低目标30%防御和伤害效果,持续60秒 | I22: 10052 | L22: 天赋2 | M22: 职业专精 | N22: 元素引力波技能造成伤害提升50%;光之击冷却时间降低5秒;能量之地技能伤害提升20% | AP22: 被动 | AR22: 职业专属被动 | AS22: 受到攻击有3%概率给自己释放一个护盾 | AV22: 10051 | AX22: 52级 | AY22: 天赋1 | AZ22: 职业专精 | BA22: 大魔导师之影冷却时间降低20秒,精灵轰击取消吟唱改为立即施法,心灵治愈冷却时间缩减5秒 | CN22: 10043 | CQ22: 天赋3 | CR22: 职业专精 | CS22: 冰封之地: 伤害提升20% 蓄力一击:伤害提升50% 狂魔之球:伤害提升至50%
D23: 30 | F23: 光之能量 | G23: 对前方区域释放一个区域性伤害,每秒造成50%伤害,持续6秒 | I23: 10053 | L23: 天赋3 | M23: 时间掌握 | N23: 技能冷却时间降低10% | AF23: 无技能效果 | AI23: 无技能效果 | AK23: 单体 | AL23: 无技能效果 | AR23: 职业光环 | AS23: 附近敌方单位受到伤害额外提升10% | AV23: 10052 | AY23: 天赋2 | AZ23: 法术连击 | BA23: 释放技能有15%概率连续释放2次 | BN23: 远程被动 | CN23: 10051 | CP23: 42级 | CQ23: 天赋1 | CR23: 射击穿透 | CS23: 物理穿透提升10%
D24: 35 | F24: 光之斩 | G24: 蓄力1秒,对目标快速突击,所经过的直线区域造成300%伤害,并眩晕1秒 | AD24: 普通技能效果 | AF24: 2.5 | AG24: 300 | AI24: 2.5 | AJ24: 1500 | AK24: 3 | AL24: 2.5 | AM24: 300 | AN24: =AL24*1500 -> 3750 | AO24: =AM24 -> 300 | AP24: =AO24+AN24 -> 4050 | AV24: 10053 | AY24: 天赋3 | AZ24: 被动反击 | BA24: 受到攻击有20%概率对目标造成2秒眩晕,此效果10秒触发一次 | BN24: 精准射击 | BO24: 攻击目标命中增加10% | BU24: E3D-Skill-Blade-Orange1(Clone) | BW24: 轻甲 | BY24: 猎影 | CN24: 10052 | CQ24: 天赋2 | CR24: 怒气恢复 | CS24: 怒气上限提升至120,怒气恢复速度提升10%
D25: 被动 | F25: 职业专属被动 | G25: 普通攻击暴击后有10%概率给自己的武器附加光剑属性 | N25: 刃甲 | S25: 战士 | AE25: =AF25-AF24 -> 0 | AF25: 2.5 | AG25: 300 | AI25: 2.5 | AJ25: 1500 | AK25: 3 | AL25: 2.5 | AM25: 300 | AN25: =AL25*1500 -> 3750 | AO25: =AM25 -> 300 | AP25: =AO25+AN25 -> 4050 | BA25: 爆裂燃烧冷却CD降低3秒 | BS25: Jiansheng_Atk_Q(Clone) | BV25: Binggong_Atk_W(Clone)（改） | BX25: 30 | BY25: 灼热之箭 | BZ25: 对目标区域造成伤害并附加灼热BUFF，每秒损失一定生命值,可叠加 | CG25: Eff_Skill_BaoZha_46 | CN25: 10053 | CQ25: 天赋3 | CR25: 职业升阶 | CS25: 火舌守卫：冷却时间降低5秒 剑气:技能会使目标的移动速度降低30% 野兽呼唤:怪物伤害提升20%
F26: 职业光环 | G26: 附近友方玩家暴击概率提升+5% | R26: 特殊技能书 | S26: 1 | T26: 基础剑术 | U26: 攻击有一定概率 | AD26: =1000*AE26 -> 0 | AE26: =AF26-AF25 -> 0 | AF26: 2.5 | AG26: 600 | AI26: 2.5 | AJ26: 2000 | AK26: 3 | AL26: 2.5 | AM26: 600 | AN26: =AL26*1500 -> 3750 | AO26: =AM26 -> 600 | AP26: =AO26+AN26 -> 4350 | AZ26: 生命恢复 | BA26: 新增技能生命回复,可以立即回复自身20%生命,15秒冷却时间 | BT26: Binggong_Atk_W(Clone) | BV26: 50_RFX_Tonado_Elect | BX26: 35 | BY26: 眩晕射击 | BZ26: 对目标矩形范围内的敌人造成伤害并进行眩晕 | CG26: Eff_Skill_BaoZha_47 | CN26: 10051 | CP26: 52级 | CQ26: 天赋1 | CR26: 攻击之力 | CS26: 每次攻击目标会有一定概率使其所有防御降低为0,持续5秒
K27: 缺点 | N27: 附加新技能 | S27: 2 | T27: 破防一击 | U27: 攻击有一定概率完全忽视目标全部防御 | AE27: =AF27-AF26 -> 0 | AF27: 2.5 | AG27: 1000 | AI27: 2.5 | AJ27: 2500 | AK27: 3 | AL27: 2.5 | AM27: 1000 | AN27: =AL27*1500 -> 3750 | AO27: =AM27 -> 1000 | AP27: =AO27+AN27 -> 4750 | AR27: 治愈之术 | AS27: 立即对自己和目标恢复相当于自身攻击50%的生命值,如果目标是敌方单位,则造成100%伤害 | AZ27: 强击 | BA27: 新增强击技能,立即对目标造成200%伤害 | BU27: BlindBase(Clone) 蓄力 | BX27: 40 | BY27: 蓄力一击 | BZ27: 蓄力对目标造成大量伤害 | CG27: Eff_Skill_ChiXu_16 | CJ27: Eff_Skill_ChiXu_16_XuLi | CN27: 10052 | CQ27: 天赋2 | CR27: 爆炸射击 | CS27: 对目标发射散射攻击,散射攻击目标命中目标后会对附近单位造成200%范围伤害
B28: 魔神武士 | D28: 20 | F28: 能量吸附 | G28: 能把附近的怪物吸附到自身的脚下,并立即在脚下释放一个范围性技能,造成200%伤害 | K28: 缺少对团队之间的技能加成 | N28: 增强某个技能的伤害和持续时间,新增自己释放和目标释放的buff | S28: 3 | AE28: =AF28-AF27 -> 0 | AF28: 2.5 | AG28: 1500 | AI28: 2.5 | AJ28: 3000 | AK28: 3 | AL28: 2.5 | AM28: 1500 | AN28: =AL28*1500 -> 3750 | AO28: =AM28 -> 1500 | AP28: =AO28+AN28 -> 5250 | AZ28: 伤害上升 | BA28: 裂地击和裂波击伤害提升50% | BS28: E3D-Skill-Continuous-Orange-Once(Clone) | BV28: E3D-Strong-Distort-Spread-Blue(Clone) | BX28: 50 | BY28: 剑雨 | BZ28: 对目标区域造成持续性伤害,物伤加成 | CG28: Eff_Skill_ChiXu_17 | CN28: 10053 | CQ28: 天赋3 | CR28: 多重射击 | CS28: 攻击会对目标及附近的单位同时攻击
D29: 25 | F29: 狂魔状态 | G29: 开启后,每秒损失当前5%血量,伤害提升40%,每次攻击可以吸取目标20%的生命来回复自身的血量 | N29: 增强属性值 | S29: 4 | AE29: =AF29-AF28 -> 0 | AF29: 2.5 | AG29: 2000 | AI29: 2.5 | AJ29: 3500 | AK29: 3 | AL29: 2.5 | AM29: 2000 | AN29: =AL29*1500 -> 3750 | AO29: =AM29 -> 2000 | AP29: =AO29+AN29 -> 5750 | AZ29: 技能刷新 | BA29: 每次攻击暴击后5%的概率自动触发裂地斩技能,且不影响主技能的冷却时间 | BN29: 近战被动 | BO29: 每次攻击有一定概率触发重击,无视目标防御造成伤害
D30: 30 | F30: 狂魔之球 | G30: 释放出6个法球,持续对周围造成每秒造成100%伤害,持续6秒 | N30: 替换技能 | S30: 5 | AZ30: 进退自由 | BA30: 跳跃斩和冲锋斩会对目标区域内造成3秒眩晕的效果 | BN30: 职业被动 | BV30: E3D-Skill-Continuous-Blue(Clone) | BW30: 觉醒 | BZ30: 向前方发射5波射击阵 | CG30: Eff_Skill_ChiXu_18
D31: 35 | F31: 狂魔之地 | G31: 腐蚀脚下一块土地,在此范围内的目标每秒损失30%伤害,自身伤害提升30%,目标移动速度降低30%,持续10秒 | J31: 伤害评判 | K31: 伤害 | L31: 附带 | N31: 增强某个Buff的属性和持续时间 | S31: 6 | AF31: 有技能效果 | AI31: 有技能效果 | AZ31: 圣光之速 | BA31: 圣光之速,提升自身移动速度200%,持续6秒
D32: 被动 | F32: 职业专属被动 | G32: 闪避目标攻击后,有3%概率召唤出一个法球围绕自己飞行,法球会对碰撞的单位造成20%的伤害,每个法球持续6秒 | I32: =K32/5*2 -> 60 | J32: 1 | K32: 150 | L32: 200 | S32: 7 | AF32: 2 | AG32: 210 | AI32: 2 | AJ32: 1050 | AL32: 2 | AM32: =AM24*0.7 -> 210 | AO32: 2136 | AP32: 836 | AQ32: =AO32-AP32 -> 1300 | AZ32: 暴击上升 | BA32: 暴击概率永久提升5% | BN32: 通用多余技能 | BW32: 被动
F33: 职业光环 | G33: 附近友方玩家攻击提升100点 | I33: =K33/5*2 -> 70 | J33: 2 | K33: 175 | L33: 280 | N33: 狂战士,血量越低,伤害越高,增加基础回血技能 | Q33: 15平方 | S33: 8 | AE33: =AF33-AF32 -> 0 | AF33: 2 | AG33: 210 | AI33: 2 | AJ33: 1050 | AL33: 2 | AM33: =AM25*0.7 -> 210 | AQ33: =AQ32*2.25 -> 2925 | AR33: =AQ33*0.3 -> 877.5 | AZ33: 职业专精 | BA33: 职业专属被动技能效果提升至5% | BN33: 沉睡效果 | BO33: 沉睡过程中无法使用技能无法移动,但是被任意伤害攻击则会苏醒 | BY33: 职业光环 | BZ33: 重击概率提升5% | CG33: E3D-Skill-Blast-Blue(Clone)
I34: =K34/5*2 -> 80 | J34: 3 | K34: 200 | L34: 360 | S34: 9 | AE34: =AF34-AF33 -> 0 | AF34: 2 | AG34: 420 | AI34: 2 | AJ34: 1400 | AK34: =AJ34-AJ33 -> 350 | AL34: 2 | AM34: =AM26*0.7 -> 420 | AZ34: 技能专精 | BA34: 元素护盾: 护盾效果提升50% 光能斩:伤害提升50% 能量吸附:伤害提升50% | BZ34: 攻击有10%概率降低眩晕目标1秒
I35: =K35/5*2 -> 90 | J35: 4 | K35: 225 | L35: 420 | S35: 10 | AE35: =AF35-AF34 -> 0 | AF35: 2 | AG35: 700 | AI35: 2 | AJ35: 1750 | AK35: =AJ35-AJ34 -> 350 | AL35: 2 | AM35: =AM27*0.7 -> 700 | AZ35: 防御之盾 | BA35: 每20秒自动自身释放一个护盾,护盾可以抵抗50%伤害,持续20秒
I36: =K36/5*2 -> 100 | J36: 5 | K36: 250 | L36: 500 | AE36: =AF36-AF35 -> 0 | AF36: 2 | AG36: 1050 | AI36: 2 | AJ36: 2100 | AK36: =AJ36-AJ35 -> 350 | AL36: 2 | AM36: =AM28*0.7 -> 1050 | AZ36: 猛击 | BA36: 新增技能：猛击 立即对目标造成300%伤害,如果目标血量低于30%,伤害提升50%
F37: 饰品技能 | AE37: =AF37-AF36 -> 0 | AF37: 2 | AG37: 1400 | AI37: 2 | AJ37: 2450 | AK37: =AJ37-AJ36 -> 350 | AL37: 2 | AM37: =AM29*0.7 -> 1400 | AZ37: 技能升阶 | BA37: 元素光球:对触碰到的玩家移动速度降低50% 光剑攻击:持续时间延长至10秒 狂魔状态:伤害提升至60% | BW37: 重甲 | BY37: 驯兽师 | CO37: 熊 | CP37: 1 | CQ37: 嘲讽
D38: 14080001 | E38: 治愈之秋 | F38: 治愈 | G38: 恢复己方自身生命10%+1000点生命值 | J38: 效果 | AZ38: 攻击恢复 | BA38: 普通攻击有3%概率回复自身最大生命的1% | BV38: 54_RFX_TinkerbellLight1 / 53_RFX_TinkerbellLight1 | BX38: 30 | BY38: 野兽爆发 | BZ38: 恢复召唤的野兽30%生命值,且自身和宝宝同时攻击速度和伤害提升50%,持续10秒 | CG38: Eff_Skill_BaoZha_48 | CP38: 2 | CQ38: 嘲讽 | CR38: 重殴(附带群体伤害)
D39: 14080002 | E39: 森之精灵 | G39: 对目标区域每秒造成100%伤害,持续9秒 | J39: 1 | K39: 120 | L39: 100 | AZ39: 生命护盾 | BA39: 当生命低于30%时,自动获得一个护盾,可以抵抗相当于自身100%生命的伤害,30秒冷却时间 | BS39: Zhaosange_defender_Q_1(Clone) | BU39: visionBuff(Clone) | BX39: 35 | BY39: 狩猎标记 | BZ39: 对标记的目标,使其受到的伤害额外提升20%,并使野兽会持续性的攻击目标 | CG39: Eff_Skill_ShouLie | CI39: Eff_Skill_ShouLieChiXu | CP39: 3 | CQ39: 嘲讽 | CS39: 重击(附带概率眩晕)
D40: 14080003 | E40: 疾风之灵 | G40: 移动速度提升50%,持续12秒 | J40: 2 | K40: 140 | L40: 150 | AZ40: 职业专精 | BA40: 元素烈波: 触碰到的目标移动速度降低50%,持续6秒 光之能量:伤害范围增加,伤害提升至75% 狂魔之球:伤害提升至125% | BN40: 目前给与近战猎人的定位就是攻击会回血,或者用于逃跑给目标套一层buff？ | BX40: 40 | BY40: 野兽灼烧 | BZ40: 让野兽和自身出发灼烧,对附近单位造成伤害 | CG40: Tanglang_Atk_E(Clone) | CI40: Tanxianjia_Atk_E | CP40: 4 | CQ40: 嘲讽 | CT40: 恢复,每隔一段时间恢复自身生命
...

Sheet 赛季
Q1: 每周任务 | R1: 每周怪物
B2: 6 命中 命中敌人概率提升 7 闪避 躲闪目标概率提升 8 各职业武器加成 9 一级属性 10 | Q2: =10*AC5 -> 300 | R2: =30*3*7 -> 630
B3: 野外遇到宠物或精灵的概率 | K3: 30 | O3: 大致规则
L4: 周任务 | M4: 人生任务 | O4: 每次击败40级以上领主怪物涨1-5点 | Q4: 赛季经验 | R4: 当前经验 | S4: 对应BOSS | T4: 当前天数 | U4: 累计天数 | V4: 当前BOSS经验 | W4: 主线任务数量 | X4: 单个主线任务 | Y4: 主线任务递增系数 | Z4: 当前主线任务经验 | AA4: 当前周数 | AB4: 每周任务数量 | AC4: 每周单个任务经验 | AD4: 每周任务经验 | AE4: 任务怪物比 | AH4: 奖励 | AW4: 爆率提升
H5: 每天打BOSS | K5: 单独任务 | L5: 基础任务(5个) | M5: 称号数量达到N个 | O5: 完成任务涨 | P5: 200 | Q5: 1 | R5: =ROUND(V5+Z5+AD5,-1) -> 60 | S5: 10 | T5: =S5/30 -> 0.33333333 | U5: =SUM($T$5:T5) -> 0.33333333 | V5: =S5*3 -> 30 | W5: 1.2 | X5: 150 | Y5: 0.1 | Z5: =X5*W5*Y5 -> 18 | AA5: =T5/7 -> 0.047619048 | AB5: 10 | AC5: 30 | AD5: =AC5*AB5*AA5 -> 14.285714 | AE5: =(AD5+Z5)/V5 -> 1.0761905 | AF5: 1 | AG5: 1 | AH5: 金币 | AI5: 120000 | AJ5: 10000159 | AK5: 赛季货币 | AL5: =AO5 -> 20 | AM5: 10010083 | AN5: 洗练石 | AO5: 20 | AP5: 10000143 | AQ5: 灿烂的结晶 | AR5: 5 | AS5: 10000158 | AT5: 封印之塔挑战凭证 | AU5: 2 | AW5: 0.5 | AY5: =AG5&";"&AI5&"@"&AJ5&";"&AL5&"@"&AM5&";"&AO5&"@"&AP5&";"&AR5&"@"&AS5&";"&AU5 -> 1;120000@10000159;20@10010083;20@10000143;5@10000158;2
B6: 奖励类 | J6: 1 | K6: 挑战有一次深渊类型的副本 | L6: 在野外地区击败10名玩家 | M6: 精灵数量达到N个 | P6: =R6+130 -> 250 | Q6: 2 | R6: =ROUND(V6+Z6+AD6,-1) -> 120 | S6: =S5+10 -> 20 | T6: =S6/30 -> 0.66666667 | U6: =SUM($T$5:T6) -> 1 | V6: =S6*3 -> 60 | W6: 1.2 | X6: 150 | Y6: =Y5+0.1 -> 0.2 | Z6: =X6*W6*Y6 -> 36 | AA6: =T6/7 -> 0.095238095 | AB6: 10 | AC6: 30 | AD6: =AC6*AB6*AA6 -> 28.571429 | AE6: =(AD6+Z6)/V6 -> 1.0761905 | AF6: 2 | AG6: 1 | AH6: 金币 | AI6: =AI5+20000 -> 140000 | AJ6: 10000159 | AK6: 赛季货币 | AL6: =AO6 -> 20 | AM6: 10010083 | AN6: 洗练石 | AO6: 20 | AP6: 10000143 | AQ6: 灿烂的结晶 | AR6: 5 | AS6: 10000158 | AT6: 封印之塔挑战凭证 | AU6: 2 | AW6: 1 | AY6: =AG6&";"&AI6&"@"&AJ6&";"&AL6&"@"&AM6&";"&AO6&"@"&AP6&";"&AR6&"@"&AS6&";"&AU6 -> 1;140000@10000159;20@10010083;20@10000143;5@10000158;2
A7: 奖励晶核: | B7: 贪婪 | C7: 通过击败怪物获得的金币提升5%。 | D7: =A7&B7 -> 奖励晶核:贪婪 | J7: 2 | K7: 打造一件传承的装备 | L7: 开启藏宝图10次 | M7: 坐骑数量达到N个 | P7: =R7+130 -> 320 | Q7: 3 | R7: =ROUND(V7+Z7+AD7,-1) -> 190 | S7: =S6+10 -> 30 | T7: =S7/30 -> 1 | U7: =SUM($T$5:T7) -> 2 | V7: =S7*3 -> 90 | W7: 1.2 | X7: 150 | Y7: =Y6+0.1 -> 0.3 | Z7: =X7*W7*Y7 -> 54 | AA7: =T7/7 -> 0.14285714 | AB7: 10 | AC7: 30 | AD7: =AC7*AB7*AA7 -> 42.857143 | AE7: =(AD7+Z7)/V7 -> 1.0761905 | AF7: 3 | AG7: 1 | AH7: 金币 | AI7: =AI6+20000 -> 160000 | AJ7: 10000159 | AK7: 赛季货币 | AL7: =AO7 -> 20 | AM7: 10010083 | AN7: 洗练石 | AO7: 20 | AP7: 10000143 | AQ7: 灿烂的结晶 | AR7: 5 | AS7: 10000158 | AT7: 封印之塔挑战凭证 | AU7: 2 | AW7: 1.5 | AY7: =AG7&";"&AI7&"@"&AJ7&";"&AL7&"@"&AM7&";"&AO7&"@"&AP7&";"&AR7&"@"&AS7&";"&AU7 -> 1;160000@10000159;20@10010083;20@10000143;5@10000158;2
A8: 奖励晶核: | B8: 爆率 | C8: 通过击败怪物获得的掉落奖励额外提升5%。 | D8: =A8&B8 -> 奖励晶核:爆率 | J8: 3 | K8: 合成1只战力达到8000点的宠物 | L8: 开启2次高级藏宝图 | M8: 宠物皮肤激活数量达到N个 | P8: =R8+130 -> 380 | Q8: 4 | R8: =ROUND(V8+Z8+AD8,-1) -> 250 | S8: =S7+10 -> 40 | T8: =S8/30 -> 1.3333333 | U8: =SUM($T$5:T8) -> 3.3333333 | V8: =S8*3 -> 120 | W8: 1.2 | X8: 150 | Y8: =Y7+0.1 -> 0.4 | Z8: =X8*W8*Y8 -> 72 | AA8: =T8/7 -> 0.19047619 | AB8: 10 | AC8: 30 | AD8: =AC8*AB8*AA8 -> 57.142857 | AE8: =(AD8+Z8)/V8 -> 1.0761905 | AF8: 4 | AG8: 1 | AH8: 金币 | AI8: =AI7+20000 -> 180000 | AJ8: 10000159 | AK8: 赛季货币 | AL8: =AO8 -> 20 | AM8: 10010083 | AN8: 洗练石 | AO8: 20 | AP8: 10000143 | AQ8: 灿烂的结晶 | AR8: 5 | AS8: 10000158 | AT8: 封印之塔挑战凭证 | AU8: 2 | AW8: 2 | AY8: =AG8&";"&AI8&"@"&AJ8&";"&AL8&"@"&AM8&";"&AO8&"@"&AP8&";"&AR8&"@"&AS8&";"&AU8 -> 1;180000@10000159;20@10010083;20@10000143;5@10000158;2
A9: 奖励晶核: | B9: 经验 | C9: 通过击败怪物获得的经验提升5% | D9: =A9&B9 -> 奖励晶核:经验 | J9: 4 | K9: 洗炼装备30次 | L9: 击败10个地狱级领主怪物 | M9: 战力达到N点 | P9: =R9+130 -> 440 | Q9: 5 | R9: =ROUND(V9+Z9+AD9,-1) -> 310 | S9: =S8+10 -> 50 | T9: =S9/30 -> 1.6666667 | U9: =SUM($T$5:T9) -> 5 | V9: =S9*3 -> 150 | W9: 1.2 | X9: 150 | Y9: =Y8+0.1 -> 0.5 | Z9: =X9*W9*Y9 -> 90 | AA9: =T9/7 -> 0.23809524 | AB9: 10 | AC9: 30 | AD9: =AC9*AB9*AA9 -> 71.428571 | AE9: =(AD9+Z9)/V9 -> 1.0761905 | AF9: 5 | AG9: 1 | AH9: 金币 | AI9: =AI8+20000 -> 200000 | AJ9: 10000159 | AK9: 赛季货币 | AL9: =AO9 -> 20 | AM9: 10010083 | AN9: 洗练石 | AO9: 20 | AP9: 10000143 | AQ9: 灿烂的结晶 | AR9: 5 | AS9: 10000158 | AT9: 封印之塔挑战凭证 | AU9: 3 | AW9: 2.5 | AY9: =AG9&";"&AI9&"@"&AJ9&";"&AL9&"@"&AM9&";"&AO9&"@"&AP9&";"&AR9&"@"&AS9&";"&AU9 -> 1;200000@10000159;20@10010083;20@10000143;5@10000158;3
J10: 5 | K10: 鉴定出一个3条属性的装备 | L10: 封印之塔挑战10次 | P10: =R10+130 -> 500 | Q10: 6 | R10: =ROUND(V10+Z10+AD10,-1) -> 370 | S10: =S9+10 -> 60 | T10: =S10/30 -> 2 | U10: =SUM($T$5:T10) -> 7 | V10: =S10*3 -> 180 | W10: 1.2 | X10: 150 | Y10: =Y9+0.1 -> 0.6 | Z10: =X10*W10*Y10 -> 108 | AA10: =T10/7 -> 0.28571429 | AB10: 10 | AC10: 30 | AD10: =AC10*AB10*AA10 -> 85.714286 | AE10: =(AD10+Z10)/V10 -> 1.0761905 | AF10: 6 | AG10: 1 | AH10: 金币 | AI10: =AI9+20000 -> 220000 | AJ10: 10000159 | AK10: 赛季货币 | AL10: =AO10 -> 25 | AM10: 10010083 | AN10: 洗练石 | AO10: =AO5+5 -> 25 | AP10: 10000143 | AQ10: 灿烂的结晶 | AR10: 5 | AS10: 10000158 | AT10: 封印之塔挑战凭证 | AU10: 3 | AW10: 3 | AY10: =AG10&";"&AI10&"@"&AJ10&";"&AL10&"@"&AM10&";"&AO10&"@"&AP10&";"&AR10&"@"&AS10&";"&AU10 -> 1;220000@10000159;25@10010083;25@10000143;5@10000158;3
B11: 属性类 | G11: 消费10000金币 | J11: 6 | K11: 击败3000只怪物 | L11: 获得3只全新的宠物 | P11: =R11+130 -> 570 | Q11: 7 | R11: =ROUND(V11+Z11+AD11,-1) -> 440 | S11: =S10+10 -> 70 | T11: =S11/30 -> 2.3333333 | U11: =SUM($T$5:T11) -> 9.3333333 | V11: =S11*3 -> 210 | W11: 1.2 | X11: 150 | Y11: =Y10+0.1 -> 0.7 | Z11: =X11*W11*Y11 -> 126 | AA11: =T11/7 -> 0.33333333 | AB11: 10 | AC11: 30 | AD11: =AC11*AB11*AA11 -> 100 | AE11: =(AD11+Z11)/V11 -> 1.0761905 | AF11: 7 | AG11: 1 | AH11: 金币 | AI11: =AI10+20000 -> 240000 | AJ11: 10000159 | AK11: 赛季货币 | AL11: =AO11 -> 25 | AM11: 10010083 | AN11: 洗练石 | AO11: =AO6+5 -> 25 | AP11: 10000143 | AQ11: 灿烂的结晶 | AR11: 5 | AS11: 10000158 | AT11: 封印之塔挑战凭证 | AU11: 3 | AW11: 3.5 | AY11: =AG11&";"&AI11&"@"&AJ11&";"&AL11&"@"&AM11&";"&AO11&"@"&AP11&";"&AR11&"@"&AS11&";"&AU11 -> 1;240000@10000159;25@10010083;25@10000143;5@10000158;3
A12: 属性晶核: | B12: 召唤 | C12: 召唤的宠物属性上升5%点 | D12: =A12&B12 -> 属性晶核:召唤 | J12: 7 | K12: 获得5只全新的宠物 | L12: 使用附魔道具给自己的装备附魔5次 | M12: 宠物合成出新宠物有问题 | P12: =R12+130 -> 630 | Q12: 8 | R12: =ROUND(V12+Z12+AD12,-1) -> 500 | S12: =S11+10 -> 80 | T12: =S12/30 -> 2.6666667 | U12: =SUM($T$5:T12) -> 12 | V12: =S12*3 -> 240 | W12: 1.2 | X12: 150 | Y12: =Y11+0.1 -> 0.8 | Z12: =X12*W12*Y12 -> 144 | AA12: =T12/7 -> 0.38095238 | AB12: 10 | AC12: 30 | AD12: =AC12*AB12*AA12 -> 114.28571 | AE12: =(AD12+Z12)/V12 -> 1.0761905 | AF12: 8 | AG12: 1 | AH12: 金币 | AI12: =AI11+20000 -> 260000 | AJ12: 10000159 | AK12: 赛季货币 | AL12: =AO12 -> 25 | AM12: 10010083 | AN12: 洗练石 | AO12: =AO7+5 -> 25 | AP12: 10000143 | AQ12: 灿烂的结晶 | AR12: 5 | AS12: 10000158 | AT12: 封印之塔挑战凭证 | AU12: 3 | AW12: 4 | AY12: =AG12&";"&AI12&"@"&AJ12&";"&AL12&"@"&AM12&";"&AO12&"@"&AP12&";"&AR12&"@"&AS12&";"&AU12 -> 1;260000@10000159;25@10010083;25@10000143;5@10000158;3
A13: 属性晶核: | B13: 命中 | C13: 命中敌人概率提升5% | D13: =A13&B13 -> 属性晶核:命中 | J13: 8 | K13: 封印之塔挑战20次 | L13: 使用鉴定道具给自己的装备鉴定5次 | P13: =R13+130 -> 690 | Q13: 9 | R13: =ROUND(V13+Z13+AD13,-1) -> 560 | S13: =S12+10 -> 90 | T13: =S13/30 -> 3 | U13: =SUM($T$5:T13) -> 15 | V13: =S13*3 -> 270 | W13: 1.2 | X13: 150 | Y13: =Y12+0.1 -> 0.9 | Z13: =X13*W13*Y13 -> 162 | AA13: =T13/7 -> 0.42857143 | AB13: 10 | AC13: 30 | AD13: =AC13*AB13*AA13 -> 128.57143 | AE13: =(AD13+Z13)/V13 -> 1.0761905 | AF13: 9 | AG13: 1 | AH13: 金币 | AI13: =AI12+20000 -> 280000 | AJ13: 10000159 | AK13: 赛季货币 | AL13: =AO13 -> 25 | AM13: 10010083 | AN13: 洗练石 | AO13: =AO8+5 -> 25 | AP13: 10000143 | AQ13: 灿烂的结晶 | AR13: 5 | AS13: 10000158 | AT13: 封印之塔挑战凭证 | AU13: 3 | AW13: 4.5 | AY13: =AG13&";"&AI13&"@"&AJ13&";"&AL13&"@"&AM13&";"&AO13&"@"&AP13&";"&AR13&"@"&AS13&";"&AU13 -> 1;280000@10000159;25@10010083;25@10000143;5@10000158;3
A14: 属性晶核: | B14: 闪避 | C14: 躲闪目标概率提升5% | D14: =A14&B14 -> 属性晶核:闪避 | J14: 9 | K14: 使用鉴定道具给自己的装备鉴定15次 | L14: 宠物合成5次 | P14: =R14+130 -> 750 | Q14: 10 | R14: =ROUND(V14+Z14+AD14,-1) -> 620 | S14: =S13+10 -> 100 | T14: =S14/30 -> 3.3333333 | U14: =SUM($T$5:T14) -> 18.333333 | V14: =S14*3 -> 300 | W14: 1.2 | X14: 150 | Y14: =Y13+0.1 -> 1 | Z14: =X14*W14*Y14 -> 180 | AA14: =T14/7 -> 0.47619048 | AB14: 10 | AC14: 30 | AD14: =AC14*AB14*AA14 -> 142.85714 | AE14: =(AD14+Z14)/V14 -> 1.0761905 | AF14: 10 | AG14: 1 | AH14: 金币 | AI14: =AI13+20000 -> 300000 | AJ14: 10000159 | AK14: 赛季货币 | AL14: =AO14 -> 25 | AM14: 10010083 | AN14: 洗练石 | AO14: =AO9+5 -> 25 | AP14: 10000143 | AQ14: 灿烂的结晶 | AR14: 10 | AS14: 10000158 | AT14: 封印之塔挑战凭证 | AU14: 4 | AW14: 5 | AY14: =AG14&";"&AI14&"@"&AJ14&";"&AL14&"@"&AM14&";"&AO14&"@"&AP14&";"&AR14&"@"&AS14&";"&AU14 -> 1;300000@10000159;25@10010083;25@10000143;10@10000158;4
A15: 属性晶核: | B15: 抗暴 | C15: 抗暴概率提升5% | D15: =A15&B15 -> 属性晶核:抗暴 | J15: 10 | K15: 在60级副本通关,并使自身的总输出占比大于40% | L15: 合成1只战力达到7000点的宠物 | P15: =R15+130 -> 800 | Q15: 11 | R15: =ROUND(V15+Z15+AD15,-1) -> 670 | S15: =S14+10 -> 110 | T15: =S15/30 -> 3.6666667 | U15: =SUM($T$5:T15) -> 22 | V15: =S15*3 -> 330 | W15: 1.2 | X15: 150 | Y15: 1 | Z15: =X15*W15*Y15 -> 180 | AA15: =T15/7 -> 0.52380952 | AB15: 10 | AC15: 30 | AD15: =AC15*AB15*AA15 -> 157.14286 | AE15: =(AD15+Z15)/V15 -> 1.021645 | AF15: 11 | AG15: 1 | AH15: 金币 | AI15: =AI14+20000 -> 320000 | AJ15: 10000159 | AK15: 赛季货币 | AL15: =AO15 -> 30 | AM15: 10010083 | AN15: 洗练石 | AO15: =AO10+5 -> 30 | AP15: 10000143 | AQ15: 灿烂的结晶 | AR15: 10 | AS15: 10000158 | AT15: 封印之塔挑战凭证 | AU15: 4 | AW15: 5.5 | AY15: =AG15&";"&AI15&"@"&AJ15&";"&AL15&"@"&AM15&";"&AO15&"@"&AP15&";"&AR15&"@"&AS15&";"&AU15 -> 1;320000@10000159;30@10010083;30@10000143;10@10000158;4
A16: 属性晶核: | B16: 暴击 | C16: 暴击概率提升5% | D16: =A16&B16 -> 属性晶核:暴击 | F16: 找到一个X点属性的装备 | J16: 11 | K16: 开启30次普通藏宝图 | L16: 宠物使用宠之晶洗炼达到5次 | P16: =R16+130 -> 840 | Q16: 12 | R16: =ROUND(V16+Z16+AD16,-1) -> 710 | S16: =S15+10 -> 120 | T16: =S16/30 -> 4 | U16: =SUM($T$5:T16) -> 26 | V16: =S16*3 -> 360 | W16: 1.2 | X16: 150 | Y16: 1 | Z16: =X16*W16*Y16 -> 180 | AA16: =T16/7 -> 0.57142857 | AB16: 10 | AC16: 30 | AD16: =AC16*AB16*AA16 -> 171.42857 | AE16: =(AD16+Z16)/V16 -> 0.97619048 | AF16: 12 | AG16: 1 | AH16: 金币 | AI16: =AI15+20000 -> 340000 | AJ16: 10000159 | AK16: 赛季货币 | AL16: =AO16 -> 30 | AM16: 10010083 | AN16: 洗练石 | AO16: =AO11+5 -> 30 | AP16: 10000143 | AQ16: 灿烂的结晶 | AR16: 10 | AS16: 10000158 | AT16: 封印之塔挑战凭证 | AU16: 4 | AW16: 6 | AY16: =AG16&";"&AI16&"@"&AJ16&";"&AL16&"@"&AM16&";"&AO16&"@"&AP16&";"&AR16&"@"&AS16&";"&AU16 -> 1;340000@10000159;30@10010083;30@10000143;10@10000158;4
A17: 属性晶核: | B17: 神佑 | C17: 当自身生命小于0时,有5%概率重生 | D17: =A17&B17 -> 属性晶核:神佑 | J17: 12 | K17: 钻石兑换金币10次 | L17: 宠物天梯战斗获胜次数达到10次 | P17: =R17+130 -> 890 | Q17: 13 | R17: =ROUND(V17+Z17+AD17,-1) -> 760 | S17: =S16+10 -> 130 | T17: =S17/30 -> 4.3333333 | U17: =SUM($T$5:T17) -> 30.333333 | V17: =S17*3 -> 390 | W17: 1.2 | X17: 150 | Y17: 1 | Z17: =X17*W17*Y17 -> 180 | AA17: =T17/7 -> 0.61904762 | AB17: 10 | AC17: 30 | AD17: =AC17*AB17*AA17 -> 185.71429 | AE17: =(AD17+Z17)/V17 -> 0.93772894 | AF17: 13 | AG17: 1 | AH17: 金币 | AI17: =AI16+20000 -> 360000 | AJ17: 10000159 | AK17: 赛季货币 | AL17: =AO17 -> 30 | AM17: 10010083 | AN17: 洗练石 | AO17: =AO12+5 -> 30 | AP17: 10000143 | AQ17: 灿烂的结晶 | AR17: 10 | AS17: 10000158 | AT17: 封印之塔挑战凭证 | AU17: 4 | AW17: 6.5 | AY17: =AG17&";"&AI17&"@"&AJ17&";"&AL17&"@"&AM17&";"&AO17&"@"&AP17&";"&AR17&"@"&AS17&";"&AU17 -> 1;360000@10000159;30@10010083;30@10000143;10@10000158;4
A18: 属性晶核: | B18: 物穿 | C18: 物理穿透5% | D18: =A18&B18 -> 属性晶核:物穿 | J18: 13 | K18: 击败30个领主级怪物 | L18: 装备洗炼达到10次 | P18: =R18+130 -> 930 | Q18: 14 | R18: =ROUND(V18+Z18+AD18,-1) -> 800 | S18: =S17+10 -> 140 | T18: =S18/30 -> 4.6666667 | U18: =SUM($T$5:T18) -> 35 | V18: =S18*3 -> 420 | W18: 1.2 | X18: 150 | Y18: 1 | Z18: =X18*W18*Y18 -> 180 | AA18: =T18/7 -> 0.66666667 | AB18: 10 | AC18: 30 | AD18: =AC18*AB18*AA18 -> 200 | AE18: =(AD18+Z18)/V18 -> 0.9047619 | AF18: 14 | AG18: 1 | AH18: 金币 | AI18: =AI17+20000 -> 380000 | AJ18: 10000159 | AK18: 赛季货币 | AL18: =AO18 -> 30 | AM18: 10010083 | AN18: 洗练石 | AO18: =AO13+5 -> 30 | AP18: 10000143 | AQ18: 灿烂的结晶 | AR18: 10 | AS18: 10000158 | AT18: 封印之塔挑战凭证 | AU18: 4 | AW18: 7 | AY18: =AG18&";"&AI18&"@"&AJ18&";"&AL18&"@"&AM18&";"&AO18&"@"&AP18&";"&AR18&"@"&AS18&";"&AU18 -> 1;380000@10000159;30@10010083;30@10000143;10@10000158;4
A19: 属性晶核: | B19: 魔穿 | C19: 魔法穿透5% | D19: =A19&B19 -> 属性晶核:魔穿 | J19: 14 | K19: 在野外地区击败5名玩家 | L19: 生活技能制造出20个道具 | P19: =R19+130 -> 970 | Q19: 15 | R19: =ROUND(V19+Z19+AD19,-1) -> 840 | S19: =S18+10 -> 150 | T19: =S19/30 -> 5 | U19: =SUM($T$5:T19) -> 40 | V19: =S19*3 -> 450 | W19: 1.2 | X19: 150 | Y19: 1 | Z19: =X19*W19*Y19 -> 180 | AA19: =T19/7 -> 0.71428571 | AB19: 10 | AC19: 30 | AD19: =AC19*AB19*AA19 -> 214.28571 | AE19: =(AD19+Z19)/V19 -> 0.87619048 | AF19: 15 | AG19: 1 | AH19: 金币 | AI19: =AI18+20000 -> 400000 | AJ19: 10000159 | AK19: 赛季货币 | AL19: =AO19 -> 30 | AM19: 10010083 | AN19: 洗练石 | AO19: =AO14+5 -> 30 | AP19: 10000143 | AQ19: 灿烂的结晶 | AR19: 10 | AS19: 10000158 | AT19: 封印之塔挑战凭证 | AU19: 5 | AW19: 7.5 | AY19: =AG19&";"&AI19&"@"&AJ19&";"&AL19&"@"&AM19&";"&AO19&"@"&AP19&";"&AR19&"@"&AS19&";"&AU19 -> 1;400000@10000159;30@10010083;30@10000143;10@10000158;5
A20: 属性晶核: | B20: 时间 | C20: 技能冷却5% | D20: =A20&B20 -> 属性晶核:时间 | J20: 15 | K20: 宠物使用技能书替换自身技能10次 | L20: 成功孵化5次宠物 | P20: =R20+130 -> 1040 | Q20: 16 | R20: =ROUND(V20+Z20+AD20,-1) -> 910 | S20: =S19+15 -> 165 | T20: =S20/30 -> 5.5 | U20: =SUM($T$5:T20) -> 45.5 | V20: =S20*3 -> 495 | W20: 1.2 | X20: 150 | Y20: 1 | Z20: =X20*W20*Y20 -> 180 | AA20: =T20/7 -> 0.78571429 | AB20: 10 | AC20: 30 | AD20: =AC20*AB20*AA20 -> 235.71429 | AE20: =(AD20+Z20)/V20 -> 0.83982684 | AF20: 16 | AG20: 1 | AH20: 金币 | AI20: =AI19+20000 -> 420000 | AJ20: 10000159 | AK20: 赛季货币 | AL20: =AO20 -> 35 | AM20: 10010083 | AN20: 洗练石 | AO20: =AO15+5 -> 35 | AP20: 10000143 | AQ20: 灿烂的结晶 | AR20: 10 | AS20: 10000158 | AT20: 封印之塔挑战凭证 | AU20: 5 | AW20: 8 | AY20: =AG20&";"&AI20&"@"&AJ20&";"&AL20&"@"&AM20&";"&AO20&"@"&AP20&";"&AR20&"@"&AS20&";"&AU20 -> 1;420000@10000159;35@10010083;35@10000143;10@10000158;5
A21: 属性晶核: | B21: 物伤 | C21: 物理伤害减免提升5% | D21: =A21&B21 -> 属性晶核:物伤 | J21: 16 | K21: 使用附魔道具给自己的装备附魔15次 | P21: =R21+130 -> 1130 | Q21: 17 | R21: =ROUND(V21+Z21+AD21,-1) -> 1000 | S21: =S20+15 -> 180 | T21: =S21/30 -> 6 | U21: =SUM($T$5:T21) -> 51.5 | V21: =S21*3 -> 540 | W21: 1.2 | X21: 150 | Y21: 1.1 | Z21: =X21*W21*Y21 -> 198 | AA21: =T21/7 -> 0.85714286 | AB21: 10 | AC21: 30 | AD21: =AC21*AB21*AA21 -> 257.14286 | AE21: =(AD21+Z21)/V21 -> 0.84285714 | AF21: 17 | AG21: 1 | AH21: 金币 | AI21: =AI20+20000 -> 440000 | AJ21: 10000159 | AK21: 赛季货币 | AL21: =AO21 -> 35 | AM21: 10010083 | AN21: 洗练石 | AO21: =AO16+5 -> 35 | AP21: 10000143 | AQ21: 灿烂的结晶 | AR21: 10 | AS21: 10000158 | AT21: 封印之塔挑战凭证 | AU21: 5 | AW21: 8.5 | AY21: =AG21&";"&AI21&"@"&AJ21&";"&AL21&"@"&AM21&";"&AO21&"@"&AP21&";"&AR21&"@"&AS21&";"&AU21 -> 1;440000@10000159;35@10010083;35@10000143;10@10000158;5
A22: 属性晶核: | B22: 魔伤 | C22: 魔法伤害减免提升5% | D22: =A22&B22 -> 属性晶核:魔伤 | H22: 洗炼10次装备 | J22: 17 | K22: 洗练出1个带有隐藏技能的装备 | L22: 挑战任务(3个) | P22: =R22+130 -> 1210 | Q22: 18 | R22: =ROUND(V22+Z22+AD22,-1) -> 1080 | S22: =S21+15 -> 195 | T22: =S22/30 -> 6.5 | U22: =SUM($T$5:T22) -> 58 | V22: =S22*3 -> 585 | W22: 1.2 | X22: 150 | Y22: 1.2 | Z22: =X22*W22*Y22 -> 216 | AA22: =T22/7 -> 0.92857143 | AB22: 10 | AC22: 30 | AD22: =AC22*AB22*AA22 -> 278.57143 | AE22: =(AD22+Z22)/V22 -> 0.84542125 | AF22: 18 | AG22: 1 | AH22: 金币 | AI22: =AI21+20000 -> 460000 | AJ22: 10000159 | AK22: 赛季货币 | AL22: =AO22 -> 35 | AM22: 10010083 | AN22: 洗练石 | AO22: =AO17+5 -> 35 | AP22: 10000143 | AQ22: 灿烂的结晶 | AR22: 10 | AS22: 10000158 | AT22: 封印之塔挑战凭证 | AU22: 5 | AW22: 9 | AY22: =AG22&";"&AI22&"@"&AJ22&";"&AL22&"@"&AM22&";"&AO22&"@"&AP22&";"&AR22&"@"&AS22&";"&AU22 -> 1;460000@10000159;35@10010083;35@10000143;10@10000158;5
A23: 属性晶核: | B23: 普攻 | C23: 普通攻击加成提升5% | D23: =A23&B23 -> 属性晶核:普攻 | H23: 上交一个50级的橙色装备 | J23: 18 | K23: 宠物合成10次 | L23: 挑战5次深渊类型的副本 | P23: =R23+130 -> 1290 | Q23: 19 | R23: =ROUND(V23+Z23+AD23,-1) -> 1160 | S23: =S22+15 -> 210 | T23: =S23/30 -> 7 | U23: =SUM($T$5:T23) -> 65 | V23: =S23*3 -> 630 | W23: 1.2 | X23: 150 | Y23: 1.3 | Z23: =X23*W23*Y23 -> 234 | AA23: =T23/7 -> 1 | AB23: 10 | AC23: 30 | AD23: =AC23*AB23*AA23 -> 300 | AE23: =(AD23+Z23)/V23 -> 0.84761905 | AF23: 19 | AG23: 1 | AH23: 金币 | AI23: =AI22+20000 -> 480000 | AJ23: 10000159 | AK23: 赛季货币 | AL23: =AO23 -> 35 | AM23: 10010083 | AN23: 洗练石 | AO23: =AO18+5 -> 35 | AP23: 10000143 | AQ23: 灿烂的结晶 | AR23: 10 | AS23: 10000158 | AT23: 封印之塔挑战凭证 | AU23: 5 | AW23: 9.5 | AY23: =AG23&";"&AI23&"@"&AJ23&";"&AL23&"@"&AM23&";"&AO23&"@"&AP23&";"&AR23&"@"&AS23&";"&AU23 -> 1;480000@10000159;35@10010083;35@10000143;10@10000158;5
A24: 属性晶核: | B24: 攻击 | C24: 技能攻击加成提升5% | D24: =A24&B24 -> 属性晶核:攻击 | J24: 19 | K24: 合成1只战力达到9000点的宠物 | L24: 宠物合成10次 | P24: =R24+130 -> 1380 | Q24: 20 | R24: =ROUND(V24+Z24+AD24,-1) -> 1250 | S24: =S23+15 -> 225 | T24: =S24/30 -> 7.5 | U24: =SUM($T$5:T24) -> 72.5 | V24: =S24*3 -> 675 | W24: 1.2 | X24: 150 | Y24: 1.4 | Z24: =X24*W24*Y24 -> 252 | AA24: =T24/7 -> 1.0714286 | AB24: 10 | AC24: 30 | AD24: =AC24*AB24*AA24 -> 321.42857 | AE24: =(AD24+Z24)/V24 -> 0.84952381 | AF24: 20 | AG24: 1 | AH24: 金币 | AI24: =AI23+20000 -> 500000 | AJ24: 10000159 | AK24: 赛季货币 | AL24: =AO24 -> 35 | AM24: 10010083 | AN24: 洗练石 | AO24: =AO19+5 -> 35 | AP24: 10000143 | AQ24: 灿烂的结晶 | AR24: 15 | AS24: 10000158 | AT24: 封印之塔挑战凭证 | AU24: 5 | AW24: 10 | AY24: =AG24&";"&AI24&"@"&AJ24&";"&AL24&"@"&AM24&";"&AO24&"@"&AP24&";"&AR24&"@"&AS24&";"&AU24 -> 1;500000@10000159;35@10010083;35@10000143;15@10000158;5
A25: 属性晶核: | B25: 领主伤害 | C25: 受到领主伤害降低5% | D25: =A25&B25 -> 属性晶核:领主伤害 | J25: 20 | K25: 挑战有3次深渊类型的副本 | L25: 合成1只战力达到8000点的宠物 | P25: =R25+130 -> 1460 | Q25: 21 | R25: =ROUND(V25+Z25+AD25,-1) -> 1330 | S25: =S24+15 -> 240 | T25: =S25/30 -> 8 | U25: =SUM($T$5:T25) -> 80.5 | V25: =S25*3 -> 720 | W25: 1.2 | X25: 150 | Y25: 1.5 | Z25: =X25*W25*Y25 -> 270 | AA25: =T25/7 -> 1.1428571 | AB25: 10 | AC25: 30 | AD25: =AC25*AB25*AA25 -> 342.85714 | AE25: =(AD25+Z25)/V25 -> 0.85119048 | AF25: 21 | AG25: 1 | AH25: 金币 | AI25: =AI24+20000 -> 520000 | AJ25: 10000159 | AK25: 赛季货币 | AL25: =AO25 -> 40 | AM25: 10010083 | AN25: 洗练石 | AO25: =AO20+5 -> 40 | AP25: 10000143 | AQ25: 灿烂的结晶 | AR25: 15 | AS25: 10000158 | AT25: 封印之塔挑战凭证 | AU25: 5 | AW25: 10.5 | AY25: =AG25&";"&AI25&"@"&AJ25&";"&AL25&"@"&AM25&";"&AO25&"@"&AP25&";"&AR25&"@"&AS25&";"&AU25 -> 1;520000@10000159;40@10010083;40@10000143;15@10000158;5
A26: 属性晶核: | B26: 领主减伤 | C26: 攻击领主伤害提升5% | D26: =A26&B26 -> 属性晶核:领主减伤 | G26: 在线时间达到X分钟 | J26: 21 | K26: 装备洗炼达到100次 | L26: 使用90点及以上的鉴定符去鉴定2次装备 | P26: =R26+130 -> 1550 | Q26: 22 | R26: =ROUND(V26+Z26+AD26,-1) -> 1420 | S26: =S25+15 -> 255 | T26: =S26/30 -> 8.5 | U26: =SUM($T$5:T26) -> 89 | V26: =S26*3 -> 765 | W26: 1.2 | X26: 150 | Y26: 1.6 | Z26: =X26*W26*Y26 -> 288 | AA26: =T26/7 -> 1.2142857 | AB26: 10 | AC26: 30 | AD26: =AC26*AB26*AA26 -> 364.28571 | AE26: =(AD26+Z26)/V26 -> 0.85266106 | AF26: 22 | AG26: 1 | AH26: 金币 | AI26: =AI25+20000 -> 540000 | AJ26: 10000159 | AK26: 赛季货币 | AL26: =AO26 -> 40 | AM26: 10010083 | AN26: 洗练石 | AO26: =AO21+5 -> 40 | AP26: 10000143 | AQ26: 灿烂的结晶 | AR26: 15 | AS26: 10000158 | AT26: 封印之塔挑战凭证 | AU26: 5 | AW26: 11 | AY26: =AG26&";"&AI26&"@"&AJ26&";"&AL26&"@"&AM26&";"&AO26&"@"&AP26&";"&AR26&"@"&AS26&";"&AU26 -> 1;540000@10000159;40@10010083;40@10000143;15@10000158;5
A27: 属性晶核: | B27: 抵抗 | C27: 抵抗负面属性概率5% | D27: =A27&B27 -> 属性晶核:抵抗 | J27: 22 | K27: 上交30个炙热印记 | L27: 钻石兑换金币5次 | P27: =R27+130 -> 1630 | Q27: 23 | R27: =ROUND(V27+Z27+AD27,-1) -> 1500 | S27: =S26+15 -> 270 | T27: =S27/30 -> 9 | U27: =SUM($T$5:T27) -> 98 | V27: =S27*3 -> 810 | W27: 1.2 | X27: 150 | Y27: 1.7 | Z27: =X27*W27*Y27 -> 306 | AA27: =T27/7 -> 1.2857143 | AB27: 10 | AC27: 30 | AD27: =AC27*AB27*AA27 -> 385.71429 | AE27: =(AD27+Z27)/V27 -> 0.85396825 | AF27: 23 | AG27: 1 | AH27: 金币 | AI27: =AI26+20000 -> 560000 | AJ27: 10000159 | AK27: 赛季货币 | AL27: =AO27 -> 40 | AM27: 10010083 | AN27: 洗练石 | AO27: =AO22+5 -> 40 | AP27: 10000143 | AQ27: 灿烂的结晶 | AR27: 15 | AS27: 10000158 | AT27: 封印之塔挑战凭证 | AU27: 5 | AW27: 11.5 | AY27: =AG27&";"&AI27&"@"&AJ27&";"&AL27&"@"&AM27&";"&AO27&"@"&AP27&";"&AR27&"@"&AS27&";"&AU27 -> 1;560000@10000159;40@10010083;40@10000143;15@10000158;5
A28: 属性晶核: | B28: 移动 | C28: 移动速度提升5% | D28: =A28&B28 -> 属性晶核:移动 | J28: 23 | K28: 上交一只6技能以上的宠物 | L28: 上交一个50级橙色的装备 | P28: =R28+130 -> 1720 | Q28: 24 | R28: =ROUND(V28+Z28+AD28,-1) -> 1590 | S28: =S27+15 -> 285 | T28: =S28/30 -> 9.5 | U28: =SUM($T$5:T28) -> 107.5 | V28: =S28*3 -> 855 | W28: 1.2 | X28: 150 | Y28: 1.8 | Z28: =X28*W28*Y28 -> 324 | AA28: =T28/7 -> 1.3571429 | AB28: 10 | AC28: 30 | AD28: =AC28*AB28*AA28 -> 407.14286 | AE28: =(AD28+Z28)/V28 -> 0.85513784 | AF28: 24 | AG28: 1 | AH28: 金币 | AI28: =AI27+20000 -> 580000 | AJ28: 10000159 | AK28: 赛季货币 | AL28: =AO28 -> 40 | AM28: 10010083 | AN28: 洗练石 | AO28: =AO23+5 -> 40 | AP28: 10000143 | AQ28: 灿烂的结晶 | AR28: 15 | AS28: 10000158 | AT28: 封印之塔挑战凭证 | AU28: 5 | AW28: 12 | AY28: =AG28&";"&AI28&"@"&AJ28&";"&AL28&"@"&AM28&";"&AO28&"@"&AP28&";"&AR28&"@"&AS28&";"&AU28 -> 1;580000@10000159;40@10010083;40@10000143;15@10000158;5
E29: 提交一个攻击大于5点资质X技能的宠物 | J29: 24 | K29: 开启3次高级藏宝图 | L29: 占领1个黄金矿 | P29: =R29+130 -> 1800 | Q29: 25 | R29: =ROUND(V29+Z29+AD29,-1) -> 1670 | S29: =S28+15 -> 300 | T29: =S29/30 -> 10 | U29: =SUM($T$5:T29) -> 117.5 | V29: =S29*3 -> 900 | W29: 1.2 | X29: 150 | Y29: 1.9 | Z29: =X29*W29*Y29 -> 342 | AA29: =T29/7 -> 1.4285714 | AB29: 10 | AC29: 30 | AD29: =AC29*AB29*AA29 -> 428.57143 | AE29: =(AD29+Z29)/V29 -> 0.85619048 | AF29: 25 | AG29: 1 | AH29: 金币 | AI29: =AI28+20000 -> 600000 | AJ29: 10000159 | AK29: 赛季货币 | AL29: =AO29 -> 40 | AM29: 10010083 | AN29: 洗练石 | AO29: =AO24+5 -> 40 | AP29: 10000143 | AQ29: 灿烂的结晶 | AR29: 15 | AS29: 10000158 | AT29: 封印之塔挑战凭证 | AU29: 5 | AW29: 12.5 | AY29: =AG29&";"&AI29&"@"&AJ29&";"&AL29&"@"&AM29&";"&AO29&"@"&AP29&";"&AR29&"@"&AS29&";"&AU29 -> 1;600000@10000159;40@10010083;40@10000143;15@10000158;5
B30: 武器加成 | J30: 25 | K30: 需求10个灿烂的结晶 | L30: 装备洗炼达到30次
A31: 武器晶核: | B31: 剑 | C31: 使用武器:剑，可以使自身伤害提升5% | D31: =A31&B31 -> 武器晶核:剑 | J31: 26 | K31: 鉴定出一个4条属性的装备 | L31: 使用珍贵的宠物蛋成功孵化两次宠物 | AE31: 每周任务 | AP31: 10000141 | AQ31: 洗炼石袋子 | AR31: 1 | AY31: 任务类型
A32: 武器晶核: | B32: 刀 | C32: 使用武器:刀，可以使自身伤害提升5% | D32: =A32&B32 -> 武器晶核:刀 | F32: 生活技能制造出50个道具 | J32: 27 | K32: 击败30个领主级怪物 | X32: 开启晶核 | Y32: 数量 | AY32: 1 | AZ32: 1 | BA32: 金币 | BB32: 100000 | BC32: 31 | BD32: 赛季经验 | BE32: 20 | BF32: 10000159 | BG32: 赛季货币 | BH32: 5 | BJ32: =AZ32&";"&BB32&"@"&BC32&";"&BE32&"@"&";"&BF32&";"&BH32 -> 1;100000@31;20@;10000159;5
A33: 武器晶核: | B33: 法杖 | C33: 使用武器:法杖，可以使自身伤害提升5% | D33: =A33&B33 -> 武器晶核:法杖 | J33: 28 | K33: 封印之塔挑战30次 | X33: 1 | Y33: 1 | Z33: ="10000162;"&Y33 -> 10000162;1 | AB33: 1 | AC33: 挑战有一次深渊类型的副本 | AF33: 1 | AG33: 1 | AH33: 金币 | AI33: 500000 | AJ33: 10000159 | AK33: 赛季货币 | AL33: 2 | AM33: 31 | AN33: 赛季经验 | AO33: 150 | AP33: 10000143 | AQ33: 灿烂的结晶 | AR33: 2 | AT33: =AJ33&";"&AM33&";"&AP33 -> 10000159;31;10000143 | AV33: =AL33&";"&AO33&";"&AR33 -> 2;150;2 | AY33: 2 | AZ33: 1 | BA33: 金币 | BB33: 150000 | BC33: 31 | BD33: 赛季经验 | BE33: 30 | BF33: 10000159 | BG33: 赛季货币 | BH33: 5 | BJ33: =AZ33&";"&BB33&"@"&BC33&";"&BE33&"@"&";"&BF33&";"&BH33 -> 1;150000@31;30@;10000159;5
A34: 武器晶核: | B34: 魔法书 | C34: 使用武器:魔法书，可以使自身伤害提升5% | D34: =A34&B34 -> 武器晶核:魔法书 | J34: 29 | K34: 上交20个炙热奖章 | L34: 高端任务(2个) | X34: 2 | Y34: 5 | Z34: ="10000162;"&Y34 -> 10000162;5 | AB34: 2 | AC34: 打造一件传承的装备 | AF34: 2 | AG34: 1 | AH34: 金币 | AI34: 500000 | AJ34: 10000159 | AK34: 赛季货币 | AL34: 2 | AM34: 31 | AN34: 赛季经验 | AO34: 150 | AP34: 10000158 | AQ34: 封印之塔挑战凭证 | AR34: 2 | AT34: =AJ34&";"&AM34&";"&AP34 -> 10000159;31;10000158 | AV34: =AL34&";"&AO34&";"&AR34 -> 2;150;2 | AY34: 3 | AZ34: 1 | BA34: 金币 | BB34: 200000 | BC34: 31 | BD34: 赛季经验 | BE34: 40 | BF34: 10000159 | BG34: 赛季货币 | BH34: 10 | BJ34: =AZ34&";"&BB34&"@"&BC34&";"&BE34&"@"&";"&BF34&";"&BH34 -> 1;200000@31;40@;10000159;10
A35: 武器晶核: | B35: 弓箭 | C35: 使用武器:弓箭，可以使自身伤害提升5% | D35: =A35&B35 -> 武器晶核:弓箭 | J35: 30 | K35: 合成1只战力达到10000点的宠物 | L35: 合成一只战力达到9000点的宠物 | X35: 3 | Y35: 10 | Z35: ="10000162;"&Y35 -> 10000162;10 | AB35: 3 | AC35: 使用鉴定道具给自己的装备鉴定15次 | AF35: 3 | AG35: 1 | AH35: 金币 | AI35: 500000 | AJ35: 10000159 | AK35: 赛季货币 | AL35: 2 | AM35: 31 | AN35: 赛季经验 | AO35: 150 | AP35: 10000162 | AQ35: 赛季晶核 | AR35: 2 | AT35: =AJ35&";"&AM35&";"&AP35 -> 10000159;31;10000162 | AV35: =AL35&";"&AO35&";"&AR35 -> 2;150;2
L36: 试炼之地输出进入排行前10 | X36: 4 | Y36: 15 | Z36: ="10000162;"&Y36 -> 10000162;15 | AB36: 4 | AC36: 洗炼装备30次 | AF36: 4 | AG36: 1 | AH36: 金币 | AI36: 500000 | AJ36: 10000159 | AK36: 赛季货币 | AL36: 2 | AM36: 31 | AN36: 赛季经验 | AO36: 150 | AP36: 10000139 | AQ36: 遗忘之水 | AR36: 1 | AT36: =AJ36&";"&AM36&";"&AP36 -> 10000159;31;10000139 | AV36: =AL36&";"&AO36&";"&AR36 -> 2;150;1
B37: 属性加成 | L37: 宠物天梯进入排行榜前10 | X37: 5 | Y37: 20 | Z37: ="10000162;"&Y37 -> 10000162;20 | AB37: 5 | AC37: 鉴定出一个3条属性的装备 | AF37: 5 | AG37: 1 | AH37: 金币 | AI37: 500000 | AJ37: 10000159 | AK37: 赛季货币 | AL37: 3 | AM37: 31 | AN37: 赛季经验 | AO37: 150 | AP37: 10010029 | AQ37: 传承图纸碎片 | AR37: 5 | AT37: =AJ37&";"&AM37&";"&AP37 -> 10000159;31;10010029 | AV37: =AL37&";"&AO37&";"&AR37 -> 3;150;5 | AY37: 赛季之王 | AZ37: 60级BOSS掉落 | BB37: 概率 | BD37: 刷新时间 | BE37: 48小时
A38: 属性晶核: | B38: 力量 | C38: =B38&"提升100点" -> 力量提升100点 | D38: =A38&B38 -> 属性晶核:力量 | L38: 战力排行榜进入前10 | X38: 6 | Y38: 25 | Z38: ="10000162;"&Y38 -> 10000162;25 | AB38: 6 | AC38: 击败3000只怪物 | AF38: 6 | AG38: 1 | AH38: 金币 | AI38: 500000 | AJ38: 10000159 | AK38: 赛季货币 | AL38: 3 | AM38: 31 | AN38: 赛季经验 | AO38: 150 | AP38: 10000143 | AQ38: 灿烂的结晶 | AR38: 2 | AT38: =AJ38&";"&AM38&";"&AP38 -> 10000159;31;10000143 | AV38: =AL38&";"&AO38&";"&AR38 -> 3;150;2 | AZ38: 赛季晶核 | BA38: 1 | BB38: 1
A39: 属性晶核: | B39: 智力 | C39: =B39&"提升100点" -> 智力提升100点 | D39: =A39&B39 -> 属性晶核:智力 | K39: 家园烹饪30次 | L39: 占领1个核心矿 | X39: 7 | Y39: 30 | Z39: ="10000162;"&Y39 -> 10000162;30 | AB39: 7 | AC39: 获得5只全新的宠物 | AF39: 7 | AG39: 1 | AH39: 金币 | AI39: 500000 | AJ39: 10000159 | AK39: 赛季货币 | AL39: 3 | AM39: 31 | AN39: 赛季经验 | AO39: 150 | AP39: 10000157 | AQ39: 传承灵石 | AR39: 2 | AT39: =AJ39&";"&AM39&";"&AP39 -> 10000159;31;10000157 | AV39: =AL39&";"&AO39&";"&AR39 -> 3;150;2 | BA39: 1 | BB39: 0.4 | BE39: 120
A40: 属性晶核: | B40: 敏捷 | C40: =B40&"提升100点" -> 敏捷提升100点 | D40: =A40&B40 -> 属性晶核:敏捷 | G40: =6*3600 -> 21600 | J40: =14400/3600 -> 4 | L40: 上交一只6技能以上的宠物 | X40: 8 | Y40: 40 | Z40: ="10000162;"&Y40 -> 10000162;40 | AB40: 8 | AC40: 封印之塔挑战20次 | AF40: 8 | AG40: 1 | AH40: 金币 | AI40: 500000 | AJ40: 10000159 | AK40: 赛季货币 | AL40: 3 | AM40: 31 | AN40: 赛季经验 | AO40: 150 | AP40: 10010053 | AQ40: 高级生肖袋子 | AR40: 1 | AT40: =AJ40&";"&AM40&";"&AP40 -> 10000159;31;10010053 | AV40: =AL40&";"&AO40&";"&AR40 -> 3;150;1 | BA40: 1 | BB40: 0.1 | BE40: 冷却时间降低
...

Sheet 装备洗练
E2: 特殊属性 | M2: 隐藏属性 | O2: 携带部位
E3: 1001 | F3: 生命 | K3: 1 | L3: 0.01 | M3: 2001 | N3: 英勇 | O3: 武器 | P3: 攻击时附带2%生命恢复效果
E4: 1002 | F4: 攻击 | K4: 6 | L4: 0.03 | M4: 2003 | N4: 天使复苏 | O4: 衣服 | P4: 当自身血量降低值0时,有10%概率恢复自身全部生命值,10分钟只能触发一次
E5: 1003 | F5: 物防 | K5: 6 | L5: 0.01 | M5: 2004 | N5: 溅射 | O5: 武器 | P5: 每次攻击有概率对附近单位造成20%溅射伤害
E6: 1004 | F6: 魔防 | K6: 1 | L6: 0.03 | M6: 2005 | N6: 协助出战 | O6: 项链 | P6: 攻击时有概率召唤一个帮手协助你作战,帮手的属性根据自身属性变换
E7: 1005 | F7: 格挡值 | K7: 0 | L7: 0.03 | M7: 2006 | N7: 不坏之身 | O7: 护符 | P7: 受到伤害时有概率立即回复自身5%生命值
E8: 1006 | F8: 重击附加伤害 | K8: 0 | L8: 0.01 | M8: 2007 | N8: 渗透之伤 | O8: 饰品 | P8: 攻击时有概率让目标持续受到伤害,每秒使目标损失目标当前血量的1%
E9: 1007 | F9: 重击概率 | K9: 2 | L9: 0.01 | M9: 2008 | N9: 缓慢 | O9: 饰品 | P9: 攻击时有概率降低其移动速度30%,持续3秒
E10: 1008 | F10: 真实伤害 | K10: 7 | L10: 0.03 | M10: 2009 | N10: 迅捷 | O10: 鞋 | P10: 移动速度提升5%
E11: 1009 | F11: 恢复值 | K11: 2 | L11: 0.01 | M11: 2016 | N11: 百发百中 | O11: 武器 | P11: 物理攻击命中率100%,使目标无法躲避自身的任何攻击
E12: 1010 | F12: 忽视目标防御值 | K12: 0 | L12: 0.03 | M12: 2018 | N12: 精神集中 | O12: 腰带 | P12: 使用技能时有10%概率不触发自身技能时间
E13: 1011 | F13: 忽视目标魔防值 | K13: 7 | L13: 0.01 | M13: 2022 | N13: 奋力 | O13: 饰品 | P13: 攻击时有概率提升自身20%攻击,持续5秒
E14: 1012 | F14: 幸运值 | K14: 3 | L14: 0.03 | M14: 2019 | N14: 招摇 | O14: 头盔 | P14: 怪物发现目标距离+3
E15: 1013 | F15: 暴击等级 | K15: 4 | L15: 0.03 | M15: 2020 | N15: 隐匿 | O15: 头盔 | P15: 怪物发现目标距离-3
E16: 1014 | F16: 命中等级 | K16: 3 | L16: 0.03 | N16: 忽视目标 | O16: 戒指 | P16: 攻击时有概率忽视目标身上对应的防御属性
E17: 1015 | F17: 闪避等级 | K17: 4 | L17: 0.03 | N17: 贪婪 | O17: 手套 | P17: 释放技能时有概率造成1.5倍的伤害
E18: 1016 | F18: 抗暴等级 | K18: 5 | L18: 0.03 | N18: 化解 | O18: 裤子 | P18: 受到伤害时有概率使本次伤害无效
E19: 1017 | F19: 暴击概率 | K19: 5 | L19: 0.01 | N19: 冲刺 | O19: 饰品 | P19: 使用冲锋技能移动距离+2
E20: 1018 | F20: 命中概率
E21: 1019 | F21: 闪避概率
E22: 1020 | F22: 抗暴概率 | K22: 0 | L22: 0.02 | M22: 2024 | N22: 神农 | O22: 全身 | P22: 使用药剂恢复生命额外效果额外提升10%
E23: 1021 | F23: 物理伤害 | K23: 1 | L23: 0.05 | N23: 珍宝 | O23: 全身 | P23: 出售给商店时获得20倍的金币价格
E24: 1022 | F24: 魔法伤害 | K24: 2 | L24: 0.05 | N24: 简易 | O24: 全身 | P24: 穿戴此装备等级限制降低5级
E25: 1023 | F25: 物理减免 | K25: 0 | L25: 0.01 | N25: 极品 | O25: 全身 | P25: 额外发挥对应部位的装备1.1倍属性
E26: 1024 | F26: 魔法减免 | K26: 0 | L26: 0.02 | N26: 胜算 | O26: 全身 | P26: 装备最低属性和最高属性保持一致
E27: 1025 | F27: 伤害加成 | K27: 0 | L27: 0.02 | N27: 无级别 | O27: 全身 | P27: 佩戴时没有任何等级和属性要求限制
E28: 1026 | F28: 伤害减免 | K28: 0 | L28: 0.03 | N28: 虚弱 | O28: 全身 | P28: 当前部位的装备属性降低10%
E29: 1027 | F29: 攻击穿透 | K29: 0 | L29: 0.02 | N29: 宝石专精 | O29: 全身 | P29: 镶嵌的宝石属性提升20%效果
E30: 1028 | F30: 魔法穿透 | K30: 0 | L30: 0.04 | M30: 2002 | N30: 战斗恢复 | O30: 全身 | P30: 战斗中自动恢复血量的效果*2
E31: 1030 | F31: 攻击领主物理伤害加成 | K31: 3 | L31: 0.02 | N31: 攻击之手 | P31: 攻击时有概率使己方全属性提升10%,持续10秒
E32: 1031 | F32: 攻击领主魔法伤害加成 | K32: 4 | L32: 0.02 | N32: 防御之手 | P32: 受击时有概率使己方全属性提升10%,持续10秒
E33: 1032 | F33: 受到领主物理攻击减免 | K33: 5 | L33: 0.02 | N33: 恢复之手 | P33: 生命恢复时,有概率使己方全属性提升10%,持续10秒
E34: 1033 | F34: 受到领主魔法攻击减免 | K34: 6 | L34: 0.02 | N34: 急速 | P34: 当使用冲锋技能产生冷却时间时,可以使自身移动速度提升30%,持续3秒
E35: 1034 | F35: 技能冷却时间缩减
E36: 1035 | F36: 经验加成
M45: 0.1 | N45: 珍宝 | O45: 全身 | P45: 出售给商店时获得10倍的价格
M46: 0.05 | N46: 简易 | O46: 全身 | P46: 穿戴此装备等级限制降低5级
M47: 0.02 | N47: 极品 | O47: 全身 | P47: 额外发挥部位1.2倍的属性
M48: 0.02 | N48: 胜算 | O48: 全身 | P48: 装备最低属性和最高属性保持一致
M49: 0.001 | N49: 无级别 | O49: 全身 | P49: 佩戴时没有任何等级和属性要求限制
...

Sheet 装备属性
B2: 装备等级 | C2: 血量占比 | D2: 属性占比 | F2: 血量 | G2: 攻击 | H2: 物防 | I2: 魔防 | M2: 血量 | N2: 攻击 | O2: 物防 | P2: 魔防 | Q2: 系数 | U2: 属性偏向 | V2: 血量 | W2: 最大攻击 | X2: 最大物防 | Y2: 最小魔防 | AA2: 属性均衡系数 | AF2: 血量 | AG2: 最大攻击 | AH2: 最大物防 | AI2: 最小魔防
B3: 1 | C3: 5 | D3: 5 | F3: =C3*总表!D4 -> 5250 | G3: =总表!E$4*$D3 -> 500 | H3: =总表!F$4*$D3 -> 150 | I3: =总表!G$4*$D3 -> 150 | L3: 头盔 | M3: 0 | N3: 0.05 | O3: 0.1 | P3: 0.1 | Q3: =SUM(M3:P3) -> 0.25 | T3: 护甲 | U3: 布甲 | V3: 0.5 | W3: 1.35 | X3: 0.75 | Y3: 0.75 | AA3: =W3+(X3+Y3+V3)/3 -> 2.0166667 | AE3: 头盔 | AF3: =ROUND(M3*F$3,0) -> 0 | AG3: =ROUND(N3*G$3,0) -> 25 | AH3: =ROUND(O3*H$3,0) -> 15 | AI3: =ROUND(P3*I$3,0) -> 15
B4: 10 | C4: 10 | D4: 10 | F4: =C4*[1]属性总表!$E$5 -> 10500 | G4: =总表!E$4*$D4 -> 1000 | H4: =总表!F$4*$D4 -> 300 | I4: =总表!G$4*$D4 -> 300 | L4: 手套 | M4: 0 | N4: 0.065 | O4: 0 | P4: 0.3 | Q4: =SUM(M4:P4) -> 0.365 | U4: 轻甲 | V4: 1 | W4: 1 | X4: 1 | Y4: 1 | AA4: =W4+(X4+Y4+V4)/3 -> 2 | AE4: 手镯 | AF4: =ROUND(M4*F$3,0) -> 0 | AG4: =ROUND(N4*G$3,0) -> 33 | AH4: =ROUND(O4*H$3,0) -> 0 | AI4: =ROUND(P4*I$3,0) -> 45
B5: 20 | C5: 15 | D5: 15 | F5: =C5*[1]属性总表!$E$5 -> 15750 | G5: =总表!E$4*$D5 -> 1500 | H5: =总表!F$4*$D5 -> 450 | I5: =总表!G$4*$D5 -> 450 | L5: 腰带 | M5: 0.1 | N5: 0.035 | O5: 0.2 | P5: 0 | Q5: =SUM(M5:P5) -> 0.335 | U5: 重甲 | V5: 1.5 | W5: 0.75 | X5: 1.25 | Y5: 1.25 | AA5: =W5+(X5+Y5+V5)/3 -> 2.0833333 | AE5: 腰带 | AF5: =ROUND(M5*F$3,0) -> 525 | AG5: =ROUND(N5*G$3,0) -> 18 | AH5: =ROUND(O5*H$3,0) -> 30 | AI5: =ROUND(P5*I$3,0) -> 0
B6: 30 | C6: 20 | D6: 20 | F6: =C6*[1]属性总表!$E$5 -> 21000 | G6: =总表!E$4*$D6 -> 2000 | H6: =总表!F$4*$D6 -> 600 | I6: =总表!G$4*$D6 -> 600 | L6: 鞋子 | M6: 0 | N6: 0.055 | O6: 0.2 | P6: 0.2 | Q6: =SUM(M6:P6) -> 0.455 | AE6: 布靴 | AF6: =ROUND(M6*F$3,0) -> 0 | AG6: =ROUND(N6*G$3,0) -> 28 | AH6: =ROUND(O6*H$3,0) -> 30 | AI6: =ROUND(P6*I$3,0) -> 30
B7: 40 | C7: 25 | D7: 25 | F7: =C7*[1]属性总表!$E$5 -> 26250 | G7: =总表!E$4*$D7 -> 2500 | H7: =总表!F$4*$D7 -> 750 | I7: =总表!G$4*$D7 -> 750 | L7: 裤子 | M7: 0.25 | N7: 0.075 | O7: 0.1 | P7: 0 | Q7: =SUM(M7:P7) -> 0.425 | AE7: 长裤 | AF7: =ROUND(M7*F$3,0) -> 1313 | AG7: =ROUND(N7*G$3,0) -> 38 | AH7: =ROUND(O7*H$3,0) -> 15 | AI7: =ROUND(P7*I$3,0) -> 0
B8: 50 | C8: 30 | D8: 30 | F8: =C8*[1]属性总表!$E$5 -> 31500 | G8: =总表!E$4*$D8 -> 3000 | H8: =总表!F$4*$D8 -> 900 | I8: =总表!G$4*$D8 -> 900 | L8: 项链 | M8: 0 | N8: 0.15 | O8: 0.15 | P8: 0 | Q8: =SUM(M8:P8) -> 0.3 | U8: 穿戴类型 | V8: 转职名称 | AE8: 项链 | AF8: =ROUND(M8*F$3,0) -> 0 | AG8: =ROUND(N8*G$3,0) -> 75 | AH8: =ROUND(O8*H$3,0) -> 23 | AI8: =ROUND(P8*I$3,0) -> 0
L9: 戒指 | M9: 0 | N9: 0.15 | O9: 0 | P9: 0.15 | Q9: =SUM(M9:P9) -> 0.3 | T9: 战士 | U9: 轻甲 | AE9: 戒指 | AF9: =ROUND(M9*F$3,0) -> 0 | AG9: =ROUND(N9*G$3,0) -> 75 | AH9: =ROUND(O9*H$3,0) -> 0 | AI9: =ROUND(P9*I$3,0) -> 23
L10: 饰品 | M10: 0 | N10: 0 | O10: 0 | P10: 0 | Q10: =SUM(M10:P10) -> 0 | U10: 轻甲 | AE10: 饰品 | AF10: =ROUND(M10*F$3,0) -> 0 | AG10: =ROUND(N10*G$3,0) -> 0 | AH10: =ROUND(O10*H$3,0) -> 0 | AI10: =ROUND(P10*I$3,0) -> 0
B11: 品质 | D11: 2000 | L11: 护符 | M11: 0.4 | N11: 0 | O11: 0 | P11: 0 | Q11: =SUM(M11:P11) -> 0.4 | U11: 重甲 | AE11: 护符 | AF11: =ROUND(M11*F$3,0) -> 2100 | AG11: =ROUND(N11*G$3,0) -> 0 | AH11: =ROUND(O11*H$3,0) -> 0 | AI11: =ROUND(P11*I$3,0) -> 0
B12: 普通 | C12: 0.8 | D12: =C12*$D$11 -> 1600 | L12: 武器 | M12: 0 | N12: 0.42 | O12: 0 | P12: 0 | Q12: =SUM(M12:P12) -> 0.42 | AE12: 武器 | AF12: =ROUND(M12*F$3,0) -> 0 | AG12: =ROUND(N12*G$3,0) -> 210 | AH12: =ROUND(O12*H$3,0) -> 0 | AI12: =ROUND(P12*I$3,0) -> 0
B13: 套装 | C13: 1 | D13: =C13*$D$11 -> 2000 | K13: 多额外0.05(比护腿多一些好看,并且正好整体缺血量) | L13: 衣服 | M13: 0.3 | N13: 0 | O13: 0.25 | P13: 0.25 | Q13: =SUM(M13:P13) -> 0.8 | T13: 法师 | U13: 布甲 | AE13: 衣服 | AF13: =ROUND(M13*F$3,0) -> 1575 | AG13: =ROUND(N13*G$3,0) -> 0 | AH13: =ROUND(O13*H$3,0) -> 38 | AI13: =ROUND(P13*I$3,0) -> 38
B14: 极品套装 | C14: 1.2 | D14: =C14*$D$11 -> 2400 | U14: 布甲
L15: 累计总合 | M15: =SUM(M3:M13) -> 1.05 | N15: =SUM(N3:N13) -> 1 | O15: =SUM(O3:O13) -> 1 | P15: =SUM(P3:P13) -> 1 | Q15: =SUM(Q3:Q13) -> 4.05 | U15: 重甲
AE16: 头盔 | AM16: 布甲 | AN16: 0.5 | AO16: 1.35 | AP16: 0.75 | AQ16: 0.75 | AU16: 重甲 | AV16: 1.5 | AW16: 0.75 | AX16: 1.25 | AY16: 1.25
B17: 地图章节 | C17: 对应章节 | D17: 对应等级 | AC17: 掉落 | AD17: 散件 | AE17: 小木盔 | AF17: 0 | AG17: 10 | AH17: 6 | AI17: 6 | AK17: 掉落 | AL17: 散件 | AM17: 布巾 | AN17: =ROUND(AF17*AN$23,0) -> 0 | AO17: =ROUND(AG17*AO$23,0) -> 14 | AP17: =ROUND(AH17*AP$23,0) -> 5 | AQ17: =ROUND(AI17*AQ$23,0) -> 5 | AS17: 掉落 | AT17: 散件 | AU17: 铁盔 | AV17: =ROUND(AF17*AV$23,0) -> 0 | AW17: =ROUND(AG17*AW$23,0) -> 8 | AX17: =ROUND(AH17*AX$23,0) -> 8 | AY17: =ROUND(AI17*AY$23,0) -> 8
C18: 1 | D18: 15 | AC18: 掉落 | AD18: 散件 | AE18: 玄木头盔 | AF18: 0 | AG18: 18 | AH18: 10 | AI18: 10 | AK18: 掉落 | AL18: 散件 | AM18: 暗影头盔 | AN18: =ROUND(AF18*AN$23,0) -> 0 | AO18: =ROUND(AG18*AO$23,0) -> 24 | AP18: =ROUND(AH18*AP$23,0) -> 8 | AQ18: =ROUND(AI18*AQ$23,0) -> 8 | AS18: 掉落 | AT18: 散件 | AU18: 精钢头盔 | AV18: =ROUND(AF18*AV$23,0) -> 0 | AW18: =ROUND(AG18*AW$23,0) -> 14 | AX18: =ROUND(AH18*AX$23,0) -> 13 | AY18: =ROUND(AI18*AY$23,0) -> 13
C19: 2 | D19: 25 | AC19: 制作 | AD19: 套装 | AE19: 战灵头盔 | AF19: 0 | AG19: 20 | AH19: 12 | AI19: 12 | AK19: 制作 | AL19: 套装 | AM19: 灵纹头盔 | AN19: =ROUND(AF19*AN$23,0) -> 0 | AO19: =ROUND(AG19*AO$23,0) -> 27 | AP19: =ROUND(AH19*AP$23,0) -> 9 | AQ19: =ROUND(AI19*AQ$23,0) -> 9 | AS19: 制作 | AT19: 套装 | AU19: 战灵头盔 | AV19: =ROUND(AF19*AV$23,0) -> 0 | AW19: =ROUND(AG19*AW$23,0) -> 15 | AX19: =ROUND(AH19*AX$23,0) -> 15 | AY19: =ROUND(AI19*AY$23,0) -> 15
